2015-03-11 10:35:00,427 [django.request:226] [ERROR]- Internal Server Error: /_/launch
Traceback (most recent call last):
  File "/usr/local/lib/python2.7/dist-packages/django/core/handlers/base.py", line 90, in get_response
    response = middleware_method(request)
  File "/usr/local/lib/python2.7/dist-packages/django/middleware/common.py", line 71, in process_request
    if (not urlresolvers.is_valid_path(request.path_info, urlconf) and
  File "/usr/local/lib/python2.7/dist-packages/django/core/urlresolvers.py", line 573, in is_valid_path
    resolve(path, urlconf)
  File "/usr/local/lib/python2.7/dist-packages/django/core/urlresolvers.py", line 453, in resolve
    return get_resolver(urlconf).resolve(path)
  File "/usr/local/lib/python2.7/dist-packages/django/core/urlresolvers.py", line 320, in resolve
    sub_match = pattern.resolve(new_path)
  File "/usr/local/lib/python2.7/dist-packages/django/core/urlresolvers.py", line 320, in resolve
    sub_match = pattern.resolve(new_path)
  File "/usr/local/lib/python2.7/dist-packages/django/core/urlresolvers.py", line 222, in resolve
    return ResolverMatch(self.callback, args, kwargs, self.name)
  File "/usr/local/lib/python2.7/dist-packages/django/core/urlresolvers.py", line 229, in callback
    self._callback = get_callable(self._callback_str)
  File "/usr/local/lib/python2.7/dist-packages/django/utils/functional.py", line 32, in wrapper
    result = func(*args)
  File "/usr/local/lib/python2.7/dist-packages/django/core/urlresolvers.py", line 96, in get_callable
    mod = import_module(mod_name)
  File "/usr/local/lib/python2.7/dist-packages/django/utils/importlib.py", line 40, in import_module
    __import__(name)
  File "/home/cheng-shiwen/Project/kuaiwen_server/application/user/views.py", line 33
    except Exception as e:
         ^
SyntaxError: invalid syntax
2015-03-11 10:35:45,781 [django.request:226] [ERROR]- Internal Server Error: /admin/
Traceback (most recent call last):
  File "/usr/local/lib/python2.7/dist-packages/django/core/handlers/base.py", line 114, in get_response
    response = wrapped_callback(request, *callback_args, **callback_kwargs)
  File "/usr/local/lib/python2.7/dist-packages/django/contrib/admin/sites.py", line 215, in wrapper
    return self.admin_view(view, cacheable)(*args, **kwargs)
  File "/usr/local/lib/python2.7/dist-packages/django/utils/decorators.py", line 99, in _wrapped_view
    response = view_func(request, *args, **kwargs)
  File "/usr/local/lib/python2.7/dist-packages/django/views/decorators/cache.py", line 52, in _wrapped_view_func
    response = view_func(request, *args, **kwargs)
  File "/usr/local/lib/python2.7/dist-packages/django/contrib/admin/sites.py", line 194, in inner
    current_app=self.name):
  File "/usr/local/lib/python2.7/dist-packages/django/core/urlresolvers.py", line 480, in reverse
    app_list = resolver.app_dict[ns]
  File "/usr/local/lib/python2.7/dist-packages/django/core/urlresolvers.py", line 310, in app_dict
    self._populate()
  File "/usr/local/lib/python2.7/dist-packages/django/core/urlresolvers.py", line 273, in _populate
    for name in pattern.reverse_dict:
  File "/usr/local/lib/python2.7/dist-packages/django/core/urlresolvers.py", line 296, in reverse_dict
    self._populate()
  File "/usr/local/lib/python2.7/dist-packages/django/core/urlresolvers.py", line 285, in _populate
    lookups.appendlist(pattern.callback, (bits, p_pattern, pattern.default_args))
  File "/usr/local/lib/python2.7/dist-packages/django/core/urlresolvers.py", line 229, in callback
    self._callback = get_callable(self._callback_str)
  File "/usr/local/lib/python2.7/dist-packages/django/utils/functional.py", line 32, in wrapper
    result = func(*args)
  File "/usr/local/lib/python2.7/dist-packages/django/core/urlresolvers.py", line 100, in get_callable
    not module_has_submodule(import_module(parentmod), submod)):
  File "/usr/local/lib/python2.7/dist-packages/django/utils/importlib.py", line 40, in import_module
    __import__(name)
ImportError: No module named comment
2015-03-11 10:51:38,722 [django.request:226] [ERROR]- Internal Server Error: /_/open-question
Traceback (most recent call last):
  File "/usr/local/lib/python2.7/dist-packages/django/core/handlers/base.py", line 114, in get_response
    response = wrapped_callback(request, *callback_args, **callback_kwargs)
  File "/home/cheng-shiwen/Project/kuaiwen_server/application/question/views.py", line 117, in open_question
    return handle_response(result, '打开问题失败', logger, 811, e)
UnboundLocalError: local variable 'result' referenced before assignment
2015-03-27 10:47:21,428 [django.request] [WARNING]- Not Found: /
2015-03-27 10:50:29,432 [django.request] [ERROR]- Internal Server Error: /admin/user/secretuser/
Traceback (most recent call last):
  File "/usr/local/lib/python2.7/dist-packages/django/core/handlers/base.py", line 114, in get_response
    response = wrapped_callback(request, *callback_args, **callback_kwargs)
  File "/usr/local/lib/python2.7/dist-packages/django/contrib/admin/options.py", line 432, in wrapper
    return self.admin_site.admin_view(view)(*args, **kwargs)
  File "/usr/local/lib/python2.7/dist-packages/django/utils/decorators.py", line 99, in _wrapped_view
    response = view_func(request, *args, **kwargs)
  File "/usr/local/lib/python2.7/dist-packages/django/views/decorators/cache.py", line 52, in _wrapped_view_func
    response = view_func(request, *args, **kwargs)
  File "/usr/local/lib/python2.7/dist-packages/django/contrib/admin/sites.py", line 198, in inner
    return view(request, *args, **kwargs)
  File "/usr/local/lib/python2.7/dist-packages/django/utils/decorators.py", line 29, in _wrapper
    return bound_func(*args, **kwargs)
  File "/usr/local/lib/python2.7/dist-packages/django/utils/decorators.py", line 99, in _wrapped_view
    response = view_func(request, *args, **kwargs)
  File "/usr/local/lib/python2.7/dist-packages/django/utils/decorators.py", line 25, in bound_func
    return func(self, *args2, **kwargs2)
  File "/usr/local/lib/python2.7/dist-packages/django/contrib/admin/options.py", line 1411, in changelist_view
    'selection_note': _('0 of %(cnt)s selected') % {'cnt': len(cl.result_list)},
  File "/usr/local/lib/python2.7/dist-packages/django/db/models/query.py", line 77, in __len__
    self._fetch_all()
  File "/usr/local/lib/python2.7/dist-packages/django/db/models/query.py", line 854, in _fetch_all
    self._result_cache = list(self.iterator())
  File "/usr/local/lib/python2.7/dist-packages/django/db/models/query.py", line 220, in iterator
    for row in compiler.results_iter():
  File "/usr/local/lib/python2.7/dist-packages/django/db/models/sql/compiler.py", line 709, in results_iter
    for rows in self.execute_sql(MULTI):
  File "/usr/local/lib/python2.7/dist-packages/django/db/models/sql/compiler.py", line 782, in execute_sql
    cursor.execute(sql, params)
  File "/usr/local/lib/python2.7/dist-packages/django/db/backends/util.py", line 69, in execute
    return super(CursorDebugWrapper, self).execute(sql, params)
  File "/usr/local/lib/python2.7/dist-packages/django/db/backends/util.py", line 53, in execute
    return self.cursor.execute(sql, params)
  File "/usr/local/lib/python2.7/dist-packages/django/db/utils.py", line 99, in __exit__
    six.reraise(dj_exc_type, dj_exc_value, traceback)
  File "/usr/local/lib/python2.7/dist-packages/django/db/backends/util.py", line 53, in execute
    return self.cursor.execute(sql, params)
  File "/usr/local/lib/python2.7/dist-packages/django/db/backends/mysql/base.py", line 124, in execute
    return self.cursor.execute(query, args)
  File "/usr/local/lib/python2.7/dist-packages/MySQLdb/cursors.py", line 205, in execute
    self.errorhandler(self, exc, value)
  File "/usr/local/lib/python2.7/dist-packages/MySQLdb/connections.py", line 36, in defaulterrorhandler
    raise errorclass, errorvalue
OperationalError: (1054, "Unknown column 'user_secretuser.ClientIP' in 'field list'")
2015-03-27 15:29:43,946 [django.request] [WARNING]- Not Found: /_/report-question
[2015-03-27 18:29:07,882] [django.request] [ERROR] Internal Server Error: /_/report-question
Traceback (most recent call last):
  File "/usr/local/lib/python2.7/dist-packages/django/core/handlers/base.py", line 114, in get_response
    response = wrapped_callback(request, *callback_args, **callback_kwargs)
  File "/home/cheng-shiwen/Project/kuaiwen_server/application/question/views.py", line 228, in report_question
    return handle_response(result, '举报问题失败', logger, 811, e)
UnboundLocalError: local variable 'result' referenced before assignment
[2015-03-28 15:07:32,201] [django.request] [ERROR] Internal Server Error: /manage
Traceback (most recent call last):
  File "/usr/local/lib/python2.7/dist-packages/django/core/handlers/base.py", line 90, in get_response
    response = middleware_method(request)
  File "/usr/local/lib/python2.7/dist-packages/django/middleware/common.py", line 71, in process_request
    if (not urlresolvers.is_valid_path(request.path_info, urlconf) and
  File "/usr/local/lib/python2.7/dist-packages/django/core/urlresolvers.py", line 573, in is_valid_path
    resolve(path, urlconf)
  File "/usr/local/lib/python2.7/dist-packages/django/core/urlresolvers.py", line 453, in resolve
    return get_resolver(urlconf).resolve(path)
  File "/usr/local/lib/python2.7/dist-packages/django/core/urlresolvers.py", line 320, in resolve
    sub_match = pattern.resolve(new_path)
  File "/usr/local/lib/python2.7/dist-packages/django/core/urlresolvers.py", line 320, in resolve
    sub_match = pattern.resolve(new_path)
  File "/usr/local/lib/python2.7/dist-packages/django/core/urlresolvers.py", line 222, in resolve
    return ResolverMatch(self.callback, args, kwargs, self.name)
  File "/usr/local/lib/python2.7/dist-packages/django/core/urlresolvers.py", line 229, in callback
    self._callback = get_callable(self._callback_str)
  File "/usr/local/lib/python2.7/dist-packages/django/utils/functional.py", line 32, in wrapper
    result = func(*args)
  File "/usr/local/lib/python2.7/dist-packages/django/core/urlresolvers.py", line 100, in get_callable
    not module_has_submodule(import_module(parentmod), submod)):
  File "/usr/local/lib/python2.7/dist-packages/django/utils/importlib.py", line 40, in import_module
    __import__(name)
ImportError: No module named display
[2015-03-28 15:09:10,758] [django.request] [ERROR] Internal Server Error: /manage
Traceback (most recent call last):
  File "/usr/local/lib/python2.7/dist-packages/django/core/handlers/base.py", line 90, in get_response
    response = middleware_method(request)
  File "/usr/local/lib/python2.7/dist-packages/django/middleware/common.py", line 71, in process_request
    if (not urlresolvers.is_valid_path(request.path_info, urlconf) and
  File "/usr/local/lib/python2.7/dist-packages/django/core/urlresolvers.py", line 573, in is_valid_path
    resolve(path, urlconf)
  File "/usr/local/lib/python2.7/dist-packages/django/core/urlresolvers.py", line 453, in resolve
    return get_resolver(urlconf).resolve(path)
  File "/usr/local/lib/python2.7/dist-packages/django/core/urlresolvers.py", line 320, in resolve
    sub_match = pattern.resolve(new_path)
  File "/usr/local/lib/python2.7/dist-packages/django/core/urlresolvers.py", line 320, in resolve
    sub_match = pattern.resolve(new_path)
  File "/usr/local/lib/python2.7/dist-packages/django/core/urlresolvers.py", line 222, in resolve
    return ResolverMatch(self.callback, args, kwargs, self.name)
  File "/usr/local/lib/python2.7/dist-packages/django/core/urlresolvers.py", line 229, in callback
    self._callback = get_callable(self._callback_str)
  File "/usr/local/lib/python2.7/dist-packages/django/utils/functional.py", line 32, in wrapper
    result = func(*args)
  File "/usr/local/lib/python2.7/dist-packages/django/core/urlresolvers.py", line 96, in get_callable
    mod = import_module(mod_name)
  File "/usr/local/lib/python2.7/dist-packages/django/utils/importlib.py", line 40, in import_module
    __import__(name)
  File "/home/cheng-shiwen/Project/kuaiwen_server/application/display/views.py", line 8, in <module>
    from application.user.models import SecretUser, ForbidUser
ImportError: cannot import name ForbidUser
[2015-03-28 20:40:06,924] [django.request] [ERROR] Internal Server Error: /manage/user-stat
Traceback (most recent call last):
  File "/usr/local/lib/python2.7/dist-packages/django/core/handlers/base.py", line 114, in get_response
    response = wrapped_callback(request, *callback_args, **callback_kwargs)
  File "/home/cheng-shiwen/Project/kuaiwen_server/application/display/views.py", line 91, in user_stat
    return handle_response(result)
UnboundLocalError: local variable 'result' referenced before assignment
[2015-04-17 16:08:21,500] [django.request] [ERROR] Internal Server Error: /
Traceback (most recent call last):
  File "/usr/local/lib/python2.7/dist-packages/Django-1.7.7-py2.7.egg/django/core/handlers/base.py", line 98, in get_response
    resolver_match = resolver.resolve(request.path_info)
  File "/usr/local/lib/python2.7/dist-packages/Django-1.7.7-py2.7.egg/django/core/urlresolvers.py", line 343, in resolve
    for pattern in self.url_patterns:
  File "/usr/local/lib/python2.7/dist-packages/Django-1.7.7-py2.7.egg/django/core/urlresolvers.py", line 372, in url_patterns
    patterns = getattr(self.urlconf_module, "urlpatterns", self.urlconf_module)
  File "/usr/local/lib/python2.7/dist-packages/Django-1.7.7-py2.7.egg/django/core/urlresolvers.py", line 366, in urlconf_module
    self._urlconf_module = import_module(self.urlconf_name)
  File "/usr/lib/python2.7/importlib/__init__.py", line 37, in import_module
    __import__(name)
  File "/home/jing/python_app/tiaozy/tiaozy/urls.py", line 10, in <module>
    url(r'^', include('application.ssl_users.urls')),
  File "/usr/local/lib/python2.7/dist-packages/Django-1.7.7-py2.7.egg/django/conf/urls/__init__.py", line 28, in include
    urlconf_module = import_module(urlconf_module)
  File "/usr/lib/python2.7/importlib/__init__.py", line 37, in import_module
    __import__(name)
ImportError: No module named urls
[2015-04-17 16:08:22,515] [django.request] [ERROR] Internal Server Error: /favicon.ico
Traceback (most recent call last):
  File "/usr/local/lib/python2.7/dist-packages/Django-1.7.7-py2.7.egg/django/core/handlers/base.py", line 87, in get_response
    response = middleware_method(request)
  File "/usr/local/lib/python2.7/dist-packages/Django-1.7.7-py2.7.egg/django/middleware/common.py", line 72, in process_request
    if (not urlresolvers.is_valid_path(request.path_info, urlconf) and
  File "/usr/local/lib/python2.7/dist-packages/Django-1.7.7-py2.7.egg/django/core/urlresolvers.py", line 619, in is_valid_path
    resolve(path, urlconf)
  File "/usr/local/lib/python2.7/dist-packages/Django-1.7.7-py2.7.egg/django/core/urlresolvers.py", line 494, in resolve
    return get_resolver(urlconf).resolve(path)
  File "/usr/local/lib/python2.7/dist-packages/Django-1.7.7-py2.7.egg/django/core/urlresolvers.py", line 343, in resolve
    for pattern in self.url_patterns:
  File "/usr/local/lib/python2.7/dist-packages/Django-1.7.7-py2.7.egg/django/core/urlresolvers.py", line 372, in url_patterns
    patterns = getattr(self.urlconf_module, "urlpatterns", self.urlconf_module)
  File "/usr/local/lib/python2.7/dist-packages/Django-1.7.7-py2.7.egg/django/core/urlresolvers.py", line 366, in urlconf_module
    self._urlconf_module = import_module(self.urlconf_name)
  File "/usr/lib/python2.7/importlib/__init__.py", line 37, in import_module
    __import__(name)
  File "/home/jing/python_app/tiaozy/tiaozy/urls.py", line 10, in <module>
    url(r'^', include('application.ssl_users.urls')),
  File "/usr/local/lib/python2.7/dist-packages/Django-1.7.7-py2.7.egg/django/conf/urls/__init__.py", line 28, in include
    urlconf_module = import_module(urlconf_module)
  File "/usr/lib/python2.7/importlib/__init__.py", line 37, in import_module
    __import__(name)
ImportError: No module named urls
[2015-04-17 16:08:22,778] [django.request] [ERROR] Internal Server Error: /favicon.ico
Traceback (most recent call last):
  File "/usr/local/lib/python2.7/dist-packages/Django-1.7.7-py2.7.egg/django/core/handlers/base.py", line 87, in get_response
    response = middleware_method(request)
  File "/usr/local/lib/python2.7/dist-packages/Django-1.7.7-py2.7.egg/django/middleware/common.py", line 72, in process_request
    if (not urlresolvers.is_valid_path(request.path_info, urlconf) and
  File "/usr/local/lib/python2.7/dist-packages/Django-1.7.7-py2.7.egg/django/core/urlresolvers.py", line 619, in is_valid_path
    resolve(path, urlconf)
  File "/usr/local/lib/python2.7/dist-packages/Django-1.7.7-py2.7.egg/django/core/urlresolvers.py", line 494, in resolve
    return get_resolver(urlconf).resolve(path)
  File "/usr/local/lib/python2.7/dist-packages/Django-1.7.7-py2.7.egg/django/core/urlresolvers.py", line 343, in resolve
    for pattern in self.url_patterns:
  File "/usr/local/lib/python2.7/dist-packages/Django-1.7.7-py2.7.egg/django/core/urlresolvers.py", line 372, in url_patterns
    patterns = getattr(self.urlconf_module, "urlpatterns", self.urlconf_module)
  File "/usr/local/lib/python2.7/dist-packages/Django-1.7.7-py2.7.egg/django/core/urlresolvers.py", line 366, in urlconf_module
    self._urlconf_module = import_module(self.urlconf_name)
  File "/usr/lib/python2.7/importlib/__init__.py", line 37, in import_module
    __import__(name)
  File "/home/jing/python_app/tiaozy/tiaozy/urls.py", line 10, in <module>
    url(r'^', include('application.ssl_users.urls')),
  File "/usr/local/lib/python2.7/dist-packages/Django-1.7.7-py2.7.egg/django/conf/urls/__init__.py", line 28, in include
    urlconf_module = import_module(urlconf_module)
  File "/usr/lib/python2.7/importlib/__init__.py", line 37, in import_module
    __import__(name)
ImportError: No module named urls
[2015-04-17 16:24:21,632] [django.request] [ERROR] Internal Server Error: /
Traceback (most recent call last):
  File "/usr/local/lib/python2.7/dist-packages/Django-1.7.7-py2.7.egg/django/core/handlers/base.py", line 111, in get_response
    response = wrapped_callback(request, *callback_args, **callback_kwargs)
  File "/home/jing/python_app/tiaozy/application/html_files/views.py", line 5, in index
    return render_to_response('index.html')
NameError: global name 'render_to_response' is not defined
[2015-04-17 18:16:51,191] [django.request] [ERROR] Internal Server Error: /
Traceback (most recent call last):
  File "/usr/local/lib/python2.7/dist-packages/Django-1.7.7-py2.7.egg/django/core/handlers/base.py", line 98, in get_response
    resolver_match = resolver.resolve(request.path_info)
  File "/usr/local/lib/python2.7/dist-packages/Django-1.7.7-py2.7.egg/django/core/urlresolvers.py", line 345, in resolve
    sub_match = pattern.resolve(new_path)
  File "/usr/local/lib/python2.7/dist-packages/Django-1.7.7-py2.7.egg/django/core/urlresolvers.py", line 345, in resolve
    sub_match = pattern.resolve(new_path)
  File "/usr/local/lib/python2.7/dist-packages/Django-1.7.7-py2.7.egg/django/core/urlresolvers.py", line 224, in resolve
    return ResolverMatch(self.callback, args, kwargs, self.name)
  File "/usr/local/lib/python2.7/dist-packages/Django-1.7.7-py2.7.egg/django/core/urlresolvers.py", line 231, in callback
    self._callback = get_callable(self._callback_str)
  File "/usr/local/lib/python2.7/dist-packages/Django-1.7.7-py2.7.egg/django/utils/lru_cache.py", line 101, in wrapper
    result = user_function(*args, **kwds)
  File "/usr/local/lib/python2.7/dist-packages/Django-1.7.7-py2.7.egg/django/core/urlresolvers.py", line 97, in get_callable
    mod = import_module(mod_name)
  File "/usr/lib/python2.7/importlib/__init__.py", line 37, in import_module
    __import__(name)
  File "/home/jing/python_app/tiaozy/application/html_files/views.py", line 8
    return render_to_response('index.html','login_user':request.user})
                                                       ^
SyntaxError: invalid syntax
[2015-04-17 18:17:18,611] [django.request] [ERROR] Internal Server Error: /
Traceback (most recent call last):
  File "/usr/local/lib/python2.7/dist-packages/Django-1.7.7-py2.7.egg/django/core/handlers/base.py", line 111, in get_response
    response = wrapped_callback(request, *callback_args, **callback_kwargs)
  File "/home/jing/python_app/tiaozy/application/html_files/views.py", line 10, in index
    auth.logout(request)
NameError: global name 'auth' is not defined
[2015-04-17 18:17:42,683] [django.request] [ERROR] Internal Server Error: /reg/
Traceback (most recent call last):
  File "/usr/local/lib/python2.7/dist-packages/Django-1.7.7-py2.7.egg/django/core/handlers/base.py", line 111, in get_response
    response = wrapped_callback(request, *callback_args, **callback_kwargs)
  File "/home/jing/python_app/tiaozy/application/ssl_users/views.py", line 5, in reg
    return render_to_response('reg.html')
NameError: global name 'render_to_response' is not defined
[2015-04-17 18:36:05,013] [django.request] [ERROR] Internal Server Error: /reg/
Traceback (most recent call last):
  File "/usr/local/lib/python2.7/dist-packages/Django-1.7.7-py2.7.egg/django/core/handlers/base.py", line 98, in get_response
    resolver_match = resolver.resolve(request.path_info)
  File "/usr/local/lib/python2.7/dist-packages/Django-1.7.7-py2.7.egg/django/core/urlresolvers.py", line 345, in resolve
    sub_match = pattern.resolve(new_path)
  File "/usr/local/lib/python2.7/dist-packages/Django-1.7.7-py2.7.egg/django/core/urlresolvers.py", line 345, in resolve
    sub_match = pattern.resolve(new_path)
  File "/usr/local/lib/python2.7/dist-packages/Django-1.7.7-py2.7.egg/django/core/urlresolvers.py", line 224, in resolve
    return ResolverMatch(self.callback, args, kwargs, self.name)
  File "/usr/local/lib/python2.7/dist-packages/Django-1.7.7-py2.7.egg/django/core/urlresolvers.py", line 231, in callback
    self._callback = get_callable(self._callback_str)
  File "/usr/local/lib/python2.7/dist-packages/Django-1.7.7-py2.7.egg/django/utils/lru_cache.py", line 101, in wrapper
    result = user_function(*args, **kwds)
  File "/usr/local/lib/python2.7/dist-packages/Django-1.7.7-py2.7.egg/django/core/urlresolvers.py", line 97, in get_callable
    mod = import_module(mod_name)
  File "/usr/lib/python2.7/importlib/__init__.py", line 37, in import_module
    __import__(name)
  File "/home/jing/python_app/tiaozy/application/ssl_users/views.py", line 21
SyntaxError: Non-ASCII character '\xe7' in file /home/jing/python_app/tiaozy/application/ssl_users/views.py on line 21, but no encoding declared; see http://www.python.org/peps/pep-0263.html for details
[2015-04-17 18:42:55,392] [django.request] [ERROR] Internal Server Error: /reg/
Traceback (most recent call last):
  File "/usr/local/lib/python2.7/dist-packages/Django-1.7.7-py2.7.egg/django/core/handlers/base.py", line 98, in get_response
    resolver_match = resolver.resolve(request.path_info)
  File "/usr/local/lib/python2.7/dist-packages/Django-1.7.7-py2.7.egg/django/core/urlresolvers.py", line 345, in resolve
    sub_match = pattern.resolve(new_path)
  File "/usr/local/lib/python2.7/dist-packages/Django-1.7.7-py2.7.egg/django/core/urlresolvers.py", line 345, in resolve
    sub_match = pattern.resolve(new_path)
  File "/usr/local/lib/python2.7/dist-packages/Django-1.7.7-py2.7.egg/django/core/urlresolvers.py", line 224, in resolve
    return ResolverMatch(self.callback, args, kwargs, self.name)
  File "/usr/local/lib/python2.7/dist-packages/Django-1.7.7-py2.7.egg/django/core/urlresolvers.py", line 231, in callback
    self._callback = get_callable(self._callback_str)
  File "/usr/local/lib/python2.7/dist-packages/Django-1.7.7-py2.7.egg/django/utils/lru_cache.py", line 101, in wrapper
    result = user_function(*args, **kwds)
  File "/usr/local/lib/python2.7/dist-packages/Django-1.7.7-py2.7.egg/django/core/urlresolvers.py", line 97, in get_callable
    mod = import_module(mod_name)
  File "/usr/lib/python2.7/importlib/__init__.py", line 37, in import_module
    __import__(name)
  File "/home/jing/python_app/tiaozy/application/ssl_users/views.py", line 22
SyntaxError: Non-ASCII character '\xe7' in file /home/jing/python_app/tiaozy/application/ssl_users/views.py on line 22, but no encoding declared; see http://www.python.org/peps/pep-0263.html for details
[2015-04-17 18:51:11,450] [django.request] [ERROR] Internal Server Error: /reg/
Traceback (most recent call last):
  File "/usr/local/lib/python2.7/dist-packages/Django-1.7.7-py2.7.egg/django/core/handlers/base.py", line 98, in get_response
    resolver_match = resolver.resolve(request.path_info)
  File "/usr/local/lib/python2.7/dist-packages/Django-1.7.7-py2.7.egg/django/core/urlresolvers.py", line 343, in resolve
    for pattern in self.url_patterns:
  File "/usr/local/lib/python2.7/dist-packages/Django-1.7.7-py2.7.egg/django/core/urlresolvers.py", line 372, in url_patterns
    patterns = getattr(self.urlconf_module, "urlpatterns", self.urlconf_module)
  File "/usr/local/lib/python2.7/dist-packages/Django-1.7.7-py2.7.egg/django/core/urlresolvers.py", line 366, in urlconf_module
    self._urlconf_module = import_module(self.urlconf_name)
  File "/usr/lib/python2.7/importlib/__init__.py", line 37, in import_module
    __import__(name)
  File "/home/jing/python_app/tiaozy/tiaozy/urls.py", line 10, in <module>
    url(r'^', include('application.ssl_users.urls')),
  File "/usr/local/lib/python2.7/dist-packages/Django-1.7.7-py2.7.egg/django/conf/urls/__init__.py", line 28, in include
    urlconf_module = import_module(urlconf_module)
  File "/usr/lib/python2.7/importlib/__init__.py", line 37, in import_module
    __import__(name)
  File "/home/jing/python_app/tiaozy/application/ssl_users/urls.py", line 12
    url(r'^check-user','application.ssl_users.views.checkUser',name='checkUser')
      ^
SyntaxError: invalid syntax
[2015-04-17 18:51:41,062] [django.request] [ERROR] Internal Server Error: /check-user
Traceback (most recent call last):
  File "/usr/local/lib/python2.7/dist-packages/Django-1.7.7-py2.7.egg/django/core/handlers/base.py", line 111, in get_response
    response = wrapped_callback(request, *callback_args, **callback_kwargs)
  File "/home/jing/python_app/tiaozy/application/ssl_users/views.py", line 84, in checkUser
    filterResults = ssl_users.objects.filter(username=username)
NameError: global name 'ssl_users' is not defined
[2015-04-17 18:53:16,298] [django.request] [ERROR] Internal Server Error: /check-user
Traceback (most recent call last):
  File "/usr/local/lib/python2.7/dist-packages/Django-1.7.7-py2.7.egg/django/core/handlers/base.py", line 111, in get_response
    response = wrapped_callback(request, *callback_args, **callback_kwargs)
  File "/home/jing/python_app/tiaozy/application/ssl_users/views.py", line 100, in checkUser
    return HttpResponse(json_data,content_type="application/json")
NameError: global name 'HttpResponse' is not defined
[2015-04-17 18:54:25,858] [django.request] [ERROR] Internal Server Error: /check-user
Traceback (most recent call last):
  File "/usr/local/lib/python2.7/dist-packages/Django-1.7.7-py2.7.egg/django/core/handlers/base.py", line 111, in get_response
    response = wrapped_callback(request, *callback_args, **callback_kwargs)
  File "/home/jing/python_app/tiaozy/application/ssl_users/views.py", line 99, in checkUser
    return HttpResponse(json_data,content_type="application/json")
NameError: global name 'HttpResponse' is not defined
[2015-04-17 18:54:46,622] [django.request] [ERROR] Internal Server Error: /check-user
Traceback (most recent call last):
  File "/usr/local/lib/python2.7/dist-packages/Django-1.7.7-py2.7.egg/django/core/handlers/base.py", line 111, in get_response
    response = wrapped_callback(request, *callback_args, **callback_kwargs)
  File "/home/jing/python_app/tiaozy/application/ssl_users/views.py", line 99, in checkUser
    return HttpResponse(json_data,content_type="application/json")
NameError: global name 'HttpResponse' is not defined
[2015-04-17 18:58:14,221] [django.request] [ERROR] Internal Server Error: /reg-username/
Traceback (most recent call last):
  File "/usr/local/lib/python2.7/dist-packages/Django-1.7.7-py2.7.egg/django/core/handlers/base.py", line 111, in get_response
    response = wrapped_callback(request, *callback_args, **callback_kwargs)
  File "/home/jing/python_app/tiaozy/application/ssl_users/views.py", line 71, in regUsername
    auth_user = auth.authenticate(username=username,password=password)
NameError: global name 'auth' is not defined
[2015-04-17 19:09:30,706] [django.request] [ERROR] Internal Server Error: /loginout/
Traceback (most recent call last):
  File "/usr/local/lib/python2.7/dist-packages/Django-1.7.7-py2.7.egg/django/core/handlers/base.py", line 98, in get_response
    resolver_match = resolver.resolve(request.path_info)
  File "/usr/local/lib/python2.7/dist-packages/Django-1.7.7-py2.7.egg/django/core/urlresolvers.py", line 345, in resolve
    sub_match = pattern.resolve(new_path)
  File "/usr/local/lib/python2.7/dist-packages/Django-1.7.7-py2.7.egg/django/core/urlresolvers.py", line 345, in resolve
    sub_match = pattern.resolve(new_path)
  File "/usr/local/lib/python2.7/dist-packages/Django-1.7.7-py2.7.egg/django/core/urlresolvers.py", line 224, in resolve
    return ResolverMatch(self.callback, args, kwargs, self.name)
  File "/usr/local/lib/python2.7/dist-packages/Django-1.7.7-py2.7.egg/django/core/urlresolvers.py", line 231, in callback
    self._callback = get_callable(self._callback_str)
  File "/usr/local/lib/python2.7/dist-packages/Django-1.7.7-py2.7.egg/django/utils/lru_cache.py", line 101, in wrapper
    result = user_function(*args, **kwds)
  File "/usr/local/lib/python2.7/dist-packages/Django-1.7.7-py2.7.egg/django/core/urlresolvers.py", line 118, in get_callable
    (lookup_view, mod_name))
ViewDoesNotExist: Could not import application.ssl_users.views.logout. View does not exist in module application.ssl_users.views.
[2015-04-17 19:11:14,546] [django.request] [ERROR] Internal Server Error: /reg-user-info/
Traceback (most recent call last):
  File "/usr/local/lib/python2.7/dist-packages/Django-1.7.7-py2.7.egg/django/core/handlers/base.py", line 111, in get_response
    response = wrapped_callback(request, *callback_args, **callback_kwargs)
  File "/home/jing/python_app/tiaozy/application/ssl_users/views.py", line 101, in regUserInfo
    return render_to_response('reg/index.html',{'is_success':True})
  File "/usr/local/lib/python2.7/dist-packages/Django-1.7.7-py2.7.egg/django/shortcuts.py", line 25, in render_to_response
    return HttpResponse(loader.render_to_string(*args, **kwargs), **httpresponse_kwargs)
  File "/usr/local/lib/python2.7/dist-packages/Django-1.7.7-py2.7.egg/django/template/loader.py", line 170, in render_to_string
    t = get_template(template_name, dirs)
  File "/usr/local/lib/python2.7/dist-packages/Django-1.7.7-py2.7.egg/django/template/loader.py", line 144, in get_template
    template, origin = find_template(template_name, dirs)
  File "/usr/local/lib/python2.7/dist-packages/Django-1.7.7-py2.7.egg/django/template/loader.py", line 136, in find_template
    raise TemplateDoesNotExist(name)
TemplateDoesNotExist: reg/index.html
[2015-04-17 19:30:12,973] [django.request] [ERROR] Internal Server Error: /index.html
Traceback (most recent call last):
  File "/usr/local/lib/python2.7/dist-packages/Django-1.7.7-py2.7.egg/django/core/handlers/base.py", line 87, in get_response
    response = middleware_method(request)
  File "/usr/local/lib/python2.7/dist-packages/Django-1.7.7-py2.7.egg/django/middleware/common.py", line 72, in process_request
    if (not urlresolvers.is_valid_path(request.path_info, urlconf) and
  File "/usr/local/lib/python2.7/dist-packages/Django-1.7.7-py2.7.egg/django/core/urlresolvers.py", line 619, in is_valid_path
    resolve(path, urlconf)
  File "/usr/local/lib/python2.7/dist-packages/Django-1.7.7-py2.7.egg/django/core/urlresolvers.py", line 494, in resolve
    return get_resolver(urlconf).resolve(path)
  File "/usr/local/lib/python2.7/dist-packages/Django-1.7.7-py2.7.egg/django/core/urlresolvers.py", line 343, in resolve
    for pattern in self.url_patterns:
  File "/usr/local/lib/python2.7/dist-packages/Django-1.7.7-py2.7.egg/django/core/urlresolvers.py", line 372, in url_patterns
    patterns = getattr(self.urlconf_module, "urlpatterns", self.urlconf_module)
  File "/usr/local/lib/python2.7/dist-packages/Django-1.7.7-py2.7.egg/django/core/urlresolvers.py", line 366, in urlconf_module
    self._urlconf_module = import_module(self.urlconf_name)
  File "/usr/lib/python2.7/importlib/__init__.py", line 37, in import_module
    __import__(name)
  File "/home/jing/python_app/tiaozy/tiaozy/urls.py", line 11, in <module>
    url(r'^', include('application.html_files.urls')),
  File "/usr/local/lib/python2.7/dist-packages/Django-1.7.7-py2.7.egg/django/conf/urls/__init__.py", line 28, in include
    urlconf_module = import_module(urlconf_module)
  File "/usr/lib/python2.7/importlib/__init__.py", line 37, in import_module
    __import__(name)
  File "/home/jing/python_app/tiaozy/application/html_files/urls.py", line 9
    url(r'$','application.html_files.views.index',name='index'),
      ^
SyntaxError: invalid syntax
[2015-04-17 20:28:16,316] [django.request] [ERROR] Internal Server Error: /
Traceback (most recent call last):
  File "/usr/local/lib/python2.7/dist-packages/Django-1.7.7-py2.7.egg/django/core/handlers/base.py", line 98, in get_response
    resolver_match = resolver.resolve(request.path_info)
  File "/usr/local/lib/python2.7/dist-packages/Django-1.7.7-py2.7.egg/django/core/urlresolvers.py", line 345, in resolve
    sub_match = pattern.resolve(new_path)
  File "/usr/local/lib/python2.7/dist-packages/Django-1.7.7-py2.7.egg/django/core/urlresolvers.py", line 224, in resolve
    return ResolverMatch(self.callback, args, kwargs, self.name)
  File "/usr/local/lib/python2.7/dist-packages/Django-1.7.7-py2.7.egg/django/core/urlresolvers.py", line 231, in callback
    self._callback = get_callable(self._callback_str)
  File "/usr/local/lib/python2.7/dist-packages/Django-1.7.7-py2.7.egg/django/utils/lru_cache.py", line 101, in wrapper
    result = user_function(*args, **kwds)
  File "/usr/local/lib/python2.7/dist-packages/Django-1.7.7-py2.7.egg/django/core/urlresolvers.py", line 97, in get_callable
    mod = import_module(mod_name)
  File "/usr/lib/python2.7/importlib/__init__.py", line 37, in import_module
    __import__(name)
  File "/home/jing/python_app/tiaozy/application/html_files/views.py", line 18
    else
       ^
SyntaxError: invalid syntax
[2015-04-18 03:44:46,710] [django.request] [ERROR] Internal Server Error: /upload-image
Traceback (most recent call last):
  File "/usr/local/lib/python2.7/dist-packages/Django-1.7.7-py2.7.egg/django/core/handlers/base.py", line 87, in get_response
    response = middleware_method(request)
  File "/usr/local/lib/python2.7/dist-packages/Django-1.7.7-py2.7.egg/django/middleware/common.py", line 72, in process_request
    if (not urlresolvers.is_valid_path(request.path_info, urlconf) and
  File "/usr/local/lib/python2.7/dist-packages/Django-1.7.7-py2.7.egg/django/core/urlresolvers.py", line 619, in is_valid_path
    resolve(path, urlconf)
  File "/usr/local/lib/python2.7/dist-packages/Django-1.7.7-py2.7.egg/django/core/urlresolvers.py", line 494, in resolve
    return get_resolver(urlconf).resolve(path)
  File "/usr/local/lib/python2.7/dist-packages/Django-1.7.7-py2.7.egg/django/core/urlresolvers.py", line 345, in resolve
    sub_match = pattern.resolve(new_path)
  File "/usr/local/lib/python2.7/dist-packages/Django-1.7.7-py2.7.egg/django/core/urlresolvers.py", line 345, in resolve
    sub_match = pattern.resolve(new_path)
  File "/usr/local/lib/python2.7/dist-packages/Django-1.7.7-py2.7.egg/django/core/urlresolvers.py", line 224, in resolve
    return ResolverMatch(self.callback, args, kwargs, self.name)
  File "/usr/local/lib/python2.7/dist-packages/Django-1.7.7-py2.7.egg/django/core/urlresolvers.py", line 231, in callback
    self._callback = get_callable(self._callback_str)
  File "/usr/local/lib/python2.7/dist-packages/Django-1.7.7-py2.7.egg/django/utils/lru_cache.py", line 101, in wrapper
    result = user_function(*args, **kwds)
  File "/usr/local/lib/python2.7/dist-packages/Django-1.7.7-py2.7.egg/django/core/urlresolvers.py", line 97, in get_callable
    mod = import_module(mod_name)
  File "/usr/lib/python2.7/importlib/__init__.py", line 37, in import_module
    __import__(name)
  File "/home/jing/python_app/tiaozy/application/display_items/views.py", line 21
SyntaxError: Non-ASCII character '\xe4' in file /home/jing/python_app/tiaozy/application/display_items/views.py on line 21, but no encoding declared; see http://www.python.org/peps/pep-0263.html for details
[2015-04-18 03:59:09,770] [django.request] [ERROR] Internal Server Error: /upload-image
Traceback (most recent call last):
  File "/usr/local/lib/python2.7/dist-packages/Django-1.7.7-py2.7.egg/django/core/handlers/base.py", line 87, in get_response
    response = middleware_method(request)
  File "/usr/local/lib/python2.7/dist-packages/Django-1.7.7-py2.7.egg/django/middleware/common.py", line 72, in process_request
    if (not urlresolvers.is_valid_path(request.path_info, urlconf) and
  File "/usr/local/lib/python2.7/dist-packages/Django-1.7.7-py2.7.egg/django/core/urlresolvers.py", line 619, in is_valid_path
    resolve(path, urlconf)
  File "/usr/local/lib/python2.7/dist-packages/Django-1.7.7-py2.7.egg/django/core/urlresolvers.py", line 494, in resolve
    return get_resolver(urlconf).resolve(path)
  File "/usr/local/lib/python2.7/dist-packages/Django-1.7.7-py2.7.egg/django/core/urlresolvers.py", line 345, in resolve
    sub_match = pattern.resolve(new_path)
  File "/usr/local/lib/python2.7/dist-packages/Django-1.7.7-py2.7.egg/django/core/urlresolvers.py", line 345, in resolve
    sub_match = pattern.resolve(new_path)
  File "/usr/local/lib/python2.7/dist-packages/Django-1.7.7-py2.7.egg/django/core/urlresolvers.py", line 224, in resolve
    return ResolverMatch(self.callback, args, kwargs, self.name)
  File "/usr/local/lib/python2.7/dist-packages/Django-1.7.7-py2.7.egg/django/core/urlresolvers.py", line 231, in callback
    self._callback = get_callable(self._callback_str)
  File "/usr/local/lib/python2.7/dist-packages/Django-1.7.7-py2.7.egg/django/utils/lru_cache.py", line 101, in wrapper
    result = user_function(*args, **kwds)
  File "/usr/local/lib/python2.7/dist-packages/Django-1.7.7-py2.7.egg/django/core/urlresolvers.py", line 97, in get_callable
    mod = import_module(mod_name)
  File "/usr/lib/python2.7/importlib/__init__.py", line 37, in import_module
    __import__(name)
  File "/home/jing/python_app/tiaozy/application/display_items/views.py", line 21
SyntaxError: Non-ASCII character '\xe4' in file /home/jing/python_app/tiaozy/application/display_items/views.py on line 21, but no encoding declared; see http://www.python.org/peps/pep-0263.html for details
[2015-04-18 04:00:23,247] [django.request] [ERROR] Internal Server Error: /upload-image
Traceback (most recent call last):
  File "/usr/local/lib/python2.7/dist-packages/Django-1.7.7-py2.7.egg/django/core/handlers/base.py", line 87, in get_response
    response = middleware_method(request)
  File "/usr/local/lib/python2.7/dist-packages/Django-1.7.7-py2.7.egg/django/middleware/common.py", line 72, in process_request
    if (not urlresolvers.is_valid_path(request.path_info, urlconf) and
  File "/usr/local/lib/python2.7/dist-packages/Django-1.7.7-py2.7.egg/django/core/urlresolvers.py", line 619, in is_valid_path
    resolve(path, urlconf)
  File "/usr/local/lib/python2.7/dist-packages/Django-1.7.7-py2.7.egg/django/core/urlresolvers.py", line 494, in resolve
    return get_resolver(urlconf).resolve(path)
  File "/usr/local/lib/python2.7/dist-packages/Django-1.7.7-py2.7.egg/django/core/urlresolvers.py", line 345, in resolve
    sub_match = pattern.resolve(new_path)
  File "/usr/local/lib/python2.7/dist-packages/Django-1.7.7-py2.7.egg/django/core/urlresolvers.py", line 345, in resolve
    sub_match = pattern.resolve(new_path)
  File "/usr/local/lib/python2.7/dist-packages/Django-1.7.7-py2.7.egg/django/core/urlresolvers.py", line 224, in resolve
    return ResolverMatch(self.callback, args, kwargs, self.name)
  File "/usr/local/lib/python2.7/dist-packages/Django-1.7.7-py2.7.egg/django/core/urlresolvers.py", line 231, in callback
    self._callback = get_callable(self._callback_str)
  File "/usr/local/lib/python2.7/dist-packages/Django-1.7.7-py2.7.egg/django/utils/lru_cache.py", line 101, in wrapper
    result = user_function(*args, **kwds)
  File "/usr/local/lib/python2.7/dist-packages/Django-1.7.7-py2.7.egg/django/core/urlresolvers.py", line 97, in get_callable
    mod = import_module(mod_name)
  File "/usr/lib/python2.7/importlib/__init__.py", line 37, in import_module
    __import__(name)
  File "/home/jing/python_app/tiaozy/application/display_items/views.py", line 21
SyntaxError: Non-ASCII character '\xe4' in file /home/jing/python_app/tiaozy/application/display_items/views.py on line 21, but no encoding declared; see http://www.python.org/peps/pep-0263.html for details
[2015-04-18 04:00:39,017] [django.request] [ERROR] Internal Server Error: /upload-image
Traceback (most recent call last):
  File "/usr/local/lib/python2.7/dist-packages/Django-1.7.7-py2.7.egg/django/core/handlers/base.py", line 87, in get_response
    response = middleware_method(request)
  File "/usr/local/lib/python2.7/dist-packages/Django-1.7.7-py2.7.egg/django/middleware/common.py", line 72, in process_request
    if (not urlresolvers.is_valid_path(request.path_info, urlconf) and
  File "/usr/local/lib/python2.7/dist-packages/Django-1.7.7-py2.7.egg/django/core/urlresolvers.py", line 619, in is_valid_path
    resolve(path, urlconf)
  File "/usr/local/lib/python2.7/dist-packages/Django-1.7.7-py2.7.egg/django/core/urlresolvers.py", line 494, in resolve
    return get_resolver(urlconf).resolve(path)
  File "/usr/local/lib/python2.7/dist-packages/Django-1.7.7-py2.7.egg/django/core/urlresolvers.py", line 345, in resolve
    sub_match = pattern.resolve(new_path)
  File "/usr/local/lib/python2.7/dist-packages/Django-1.7.7-py2.7.egg/django/core/urlresolvers.py", line 345, in resolve
    sub_match = pattern.resolve(new_path)
  File "/usr/local/lib/python2.7/dist-packages/Django-1.7.7-py2.7.egg/django/core/urlresolvers.py", line 224, in resolve
    return ResolverMatch(self.callback, args, kwargs, self.name)
  File "/usr/local/lib/python2.7/dist-packages/Django-1.7.7-py2.7.egg/django/core/urlresolvers.py", line 231, in callback
    self._callback = get_callable(self._callback_str)
  File "/usr/local/lib/python2.7/dist-packages/Django-1.7.7-py2.7.egg/django/utils/lru_cache.py", line 101, in wrapper
    result = user_function(*args, **kwds)
  File "/usr/local/lib/python2.7/dist-packages/Django-1.7.7-py2.7.egg/django/core/urlresolvers.py", line 97, in get_callable
    mod = import_module(mod_name)
  File "/usr/lib/python2.7/importlib/__init__.py", line 37, in import_module
    __import__(name)
  File "/home/jing/python_app/tiaozy/application/display_items/views.py", line 21
SyntaxError: Non-ASCII character '\xe4' in file /home/jing/python_app/tiaozy/application/display_items/views.py on line 21, but no encoding declared; see http://www.python.org/peps/pep-0263.html for details
[2015-04-18 04:00:57,492] [django.request] [ERROR] Internal Server Error: /upload-image
Traceback (most recent call last):
  File "/usr/local/lib/python2.7/dist-packages/Django-1.7.7-py2.7.egg/django/core/handlers/base.py", line 87, in get_response
    response = middleware_method(request)
  File "/usr/local/lib/python2.7/dist-packages/Django-1.7.7-py2.7.egg/django/middleware/common.py", line 72, in process_request
    if (not urlresolvers.is_valid_path(request.path_info, urlconf) and
  File "/usr/local/lib/python2.7/dist-packages/Django-1.7.7-py2.7.egg/django/core/urlresolvers.py", line 619, in is_valid_path
    resolve(path, urlconf)
  File "/usr/local/lib/python2.7/dist-packages/Django-1.7.7-py2.7.egg/django/core/urlresolvers.py", line 494, in resolve
    return get_resolver(urlconf).resolve(path)
  File "/usr/local/lib/python2.7/dist-packages/Django-1.7.7-py2.7.egg/django/core/urlresolvers.py", line 345, in resolve
    sub_match = pattern.resolve(new_path)
  File "/usr/local/lib/python2.7/dist-packages/Django-1.7.7-py2.7.egg/django/core/urlresolvers.py", line 345, in resolve
    sub_match = pattern.resolve(new_path)
  File "/usr/local/lib/python2.7/dist-packages/Django-1.7.7-py2.7.egg/django/core/urlresolvers.py", line 224, in resolve
    return ResolverMatch(self.callback, args, kwargs, self.name)
  File "/usr/local/lib/python2.7/dist-packages/Django-1.7.7-py2.7.egg/django/core/urlresolvers.py", line 231, in callback
    self._callback = get_callable(self._callback_str)
  File "/usr/local/lib/python2.7/dist-packages/Django-1.7.7-py2.7.egg/django/utils/lru_cache.py", line 101, in wrapper
    result = user_function(*args, **kwds)
  File "/usr/local/lib/python2.7/dist-packages/Django-1.7.7-py2.7.egg/django/core/urlresolvers.py", line 97, in get_callable
    mod = import_module(mod_name)
  File "/usr/lib/python2.7/importlib/__init__.py", line 37, in import_module
    __import__(name)
  File "/home/jing/python_app/tiaozy/application/display_items/views.py", line 21
SyntaxError: Non-ASCII character '\xe4' in file /home/jing/python_app/tiaozy/application/display_items/views.py on line 21, but no encoding declared; see http://www.python.org/peps/pep-0263.html for details
[2015-04-18 04:01:39,039] [django.request] [ERROR] Internal Server Error: /upload-image
Traceback (most recent call last):
  File "/usr/local/lib/python2.7/dist-packages/Django-1.7.7-py2.7.egg/django/core/handlers/base.py", line 111, in get_response
    response = wrapped_callback(request, *callback_args, **callback_kwargs)
  File "/home/jing/python_app/tiaozy/application/display_items/views.py", line 24, in uploadImage
    logger.debug('upload-image: %s' % e)
NameError: global name 'logger' is not defined
[2015-04-18 04:02:11,166] [django.request] [ERROR] Internal Server Error: /upload-image
Traceback (most recent call last):
  File "/usr/local/lib/python2.7/dist-packages/Django-1.7.7-py2.7.egg/django/core/handlers/base.py", line 111, in get_response
    response = wrapped_callback(request, *callback_args, **callback_kwargs)
  File "/home/jing/python_app/tiaozy/application/display_items/views.py", line 28, in uploadImage
    return handle_response(result)
NameError: global name 'handle_response' is not defined
[2015-04-19 04:00:42,983] [django.request] [ERROR] Internal Server Error: /upload-image
Traceback (most recent call last):
  File "/usr/local/lib/python2.7/dist-packages/Django-1.7.7-py2.7.egg/django/core/handlers/base.py", line 111, in get_response
    response = wrapped_callback(request, *callback_args, **callback_kwargs)
  File "/home/jing/python_app/tiaozy/application/display_items/views.py", line 38, in uploadImage
    json_data = simplejson.dumps(result)
NameError: global name 'simplejson' is not defined
[2015-04-19 04:01:33,393] [django.request] [ERROR] Internal Server Error: /upload-image
Traceback (most recent call last):
  File "/usr/local/lib/python2.7/dist-packages/Django-1.7.7-py2.7.egg/django/core/handlers/base.py", line 111, in get_response
    response = wrapped_callback(request, *callback_args, **callback_kwargs)
  File "/home/jing/python_app/tiaozy/application/display_items/views.py", line 38, in uploadImage
    json_data = simplejson.dumps(result)
NameError: global name 'simplejson' is not defined
[2015-04-19 04:02:20,734] [django.request] [ERROR] Internal Server Error: /upload-image
Traceback (most recent call last):
  File "/usr/local/lib/python2.7/dist-packages/Django-1.7.7-py2.7.egg/django/core/handlers/base.py", line 87, in get_response
    response = middleware_method(request)
  File "/usr/local/lib/python2.7/dist-packages/Django-1.7.7-py2.7.egg/django/middleware/common.py", line 72, in process_request
    if (not urlresolvers.is_valid_path(request.path_info, urlconf) and
  File "/usr/local/lib/python2.7/dist-packages/Django-1.7.7-py2.7.egg/django/core/urlresolvers.py", line 619, in is_valid_path
    resolve(path, urlconf)
  File "/usr/local/lib/python2.7/dist-packages/Django-1.7.7-py2.7.egg/django/core/urlresolvers.py", line 494, in resolve
    return get_resolver(urlconf).resolve(path)
  File "/usr/local/lib/python2.7/dist-packages/Django-1.7.7-py2.7.egg/django/core/urlresolvers.py", line 345, in resolve
    sub_match = pattern.resolve(new_path)
  File "/usr/local/lib/python2.7/dist-packages/Django-1.7.7-py2.7.egg/django/core/urlresolvers.py", line 345, in resolve
    sub_match = pattern.resolve(new_path)
  File "/usr/local/lib/python2.7/dist-packages/Django-1.7.7-py2.7.egg/django/core/urlresolvers.py", line 224, in resolve
    return ResolverMatch(self.callback, args, kwargs, self.name)
  File "/usr/local/lib/python2.7/dist-packages/Django-1.7.7-py2.7.egg/django/core/urlresolvers.py", line 231, in callback
    self._callback = get_callable(self._callback_str)
  File "/usr/local/lib/python2.7/dist-packages/Django-1.7.7-py2.7.egg/django/utils/lru_cache.py", line 101, in wrapper
    result = user_function(*args, **kwds)
  File "/usr/local/lib/python2.7/dist-packages/Django-1.7.7-py2.7.egg/django/core/urlresolvers.py", line 97, in get_callable
    mod = import_module(mod_name)
  File "/usr/lib/python2.7/importlib/__init__.py", line 37, in import_module
    __import__(name)
  File "/home/jing/python_app/tiaozy/application/display_items/views.py", line 11, in <module>
    import JSON
ImportError: No module named JSON
[2015-04-19 04:03:13,951] [django.request] [ERROR] Internal Server Error: /upload-image
Traceback (most recent call last):
  File "/usr/local/lib/python2.7/dist-packages/Django-1.7.7-py2.7.egg/django/core/handlers/base.py", line 87, in get_response
    response = middleware_method(request)
  File "/usr/local/lib/python2.7/dist-packages/Django-1.7.7-py2.7.egg/django/middleware/common.py", line 72, in process_request
    if (not urlresolvers.is_valid_path(request.path_info, urlconf) and
  File "/usr/local/lib/python2.7/dist-packages/Django-1.7.7-py2.7.egg/django/core/urlresolvers.py", line 619, in is_valid_path
    resolve(path, urlconf)
  File "/usr/local/lib/python2.7/dist-packages/Django-1.7.7-py2.7.egg/django/core/urlresolvers.py", line 494, in resolve
    return get_resolver(urlconf).resolve(path)
  File "/usr/local/lib/python2.7/dist-packages/Django-1.7.7-py2.7.egg/django/core/urlresolvers.py", line 345, in resolve
    sub_match = pattern.resolve(new_path)
  File "/usr/local/lib/python2.7/dist-packages/Django-1.7.7-py2.7.egg/django/core/urlresolvers.py", line 345, in resolve
    sub_match = pattern.resolve(new_path)
  File "/usr/local/lib/python2.7/dist-packages/Django-1.7.7-py2.7.egg/django/core/urlresolvers.py", line 224, in resolve
    return ResolverMatch(self.callback, args, kwargs, self.name)
  File "/usr/local/lib/python2.7/dist-packages/Django-1.7.7-py2.7.egg/django/core/urlresolvers.py", line 231, in callback
    self._callback = get_callable(self._callback_str)
  File "/usr/local/lib/python2.7/dist-packages/Django-1.7.7-py2.7.egg/django/utils/lru_cache.py", line 101, in wrapper
    result = user_function(*args, **kwds)
  File "/usr/local/lib/python2.7/dist-packages/Django-1.7.7-py2.7.egg/django/core/urlresolvers.py", line 97, in get_callable
    mod = import_module(mod_name)
  File "/usr/lib/python2.7/importlib/__init__.py", line 37, in import_module
    __import__(name)
  File "/home/jing/python_app/tiaozy/application/display_items/views.py", line 11, in <module>
    import Json
ImportError: No module named Json
[2015-04-19 12:18:43,548] [django.request] [ERROR] Internal Server Error: /post-item/
Traceback (most recent call last):
  File "/usr/local/lib/python2.7/dist-packages/Django-1.7.7-py2.7.egg/django/core/handlers/base.py", line 98, in get_response
    resolver_match = resolver.resolve(request.path_info)
  File "/usr/local/lib/python2.7/dist-packages/Django-1.7.7-py2.7.egg/django/core/urlresolvers.py", line 345, in resolve
    sub_match = pattern.resolve(new_path)
  File "/usr/local/lib/python2.7/dist-packages/Django-1.7.7-py2.7.egg/django/core/urlresolvers.py", line 345, in resolve
    sub_match = pattern.resolve(new_path)
  File "/usr/local/lib/python2.7/dist-packages/Django-1.7.7-py2.7.egg/django/core/urlresolvers.py", line 224, in resolve
    return ResolverMatch(self.callback, args, kwargs, self.name)
  File "/usr/local/lib/python2.7/dist-packages/Django-1.7.7-py2.7.egg/django/core/urlresolvers.py", line 231, in callback
    self._callback = get_callable(self._callback_str)
  File "/usr/local/lib/python2.7/dist-packages/Django-1.7.7-py2.7.egg/django/utils/lru_cache.py", line 101, in wrapper
    result = user_function(*args, **kwds)
  File "/usr/local/lib/python2.7/dist-packages/Django-1.7.7-py2.7.egg/django/core/urlresolvers.py", line 118, in get_callable
    (lookup_view, mod_name))
ViewDoesNotExist: Could not import application.display_items.views.publishItem. View does not exist in module application.display_items.views.
[2015-04-19 12:19:43,868] [django.request] [ERROR] Internal Server Error: /post-item/
Traceback (most recent call last):
  File "/usr/local/lib/python2.7/dist-packages/Django-1.7.7-py2.7.egg/django/core/handlers/base.py", line 111, in get_response
    response = wrapped_callback(request, *callback_args, **callback_kwargs)
  File "/home/jing/python_app/tiaozy/application/display_items/views.py", line 18, in postItem
    print request.FILES['upfile[]']
  File "/usr/local/lib/python2.7/dist-packages/Django-1.7.7-py2.7.egg/django/utils/datastructures.py", line 319, in __getitem__
    raise MultiValueDictKeyError(repr(key))
MultiValueDictKeyError: "'upfile[]'"
[2015-04-19 12:20:11,680] [django.request] [ERROR] Internal Server Error: /post-item/
Traceback (most recent call last):
  File "/usr/local/lib/python2.7/dist-packages/Django-1.7.7-py2.7.egg/django/core/handlers/base.py", line 111, in get_response
    response = wrapped_callback(request, *callback_args, **callback_kwargs)
  File "/home/jing/python_app/tiaozy/application/display_items/views.py", line 18, in postItem
    print request.FILES['upfile']
  File "/usr/local/lib/python2.7/dist-packages/Django-1.7.7-py2.7.egg/django/utils/datastructures.py", line 319, in __getitem__
    raise MultiValueDictKeyError(repr(key))
MultiValueDictKeyError: "'upfile'"
[2015-04-19 12:20:35,064] [django.request] [ERROR] Internal Server Error: /post-item/
Traceback (most recent call last):
  File "/usr/local/lib/python2.7/dist-packages/Django-1.7.7-py2.7.egg/django/core/handlers/base.py", line 111, in get_response
    response = wrapped_callback(request, *callback_args, **callback_kwargs)
  File "/home/jing/python_app/tiaozy/application/display_items/views.py", line 18, in postItem
    print request.FILES['file']
  File "/usr/local/lib/python2.7/dist-packages/Django-1.7.7-py2.7.egg/django/utils/datastructures.py", line 319, in __getitem__
    raise MultiValueDictKeyError(repr(key))
MultiValueDictKeyError: "'file'"
[2015-04-19 12:22:54,060] [django.request] [ERROR] Internal Server Error: /post-item/
Traceback (most recent call last):
  File "/usr/local/lib/python2.7/dist-packages/Django-1.7.7-py2.7.egg/django/core/handlers/base.py", line 98, in get_response
    resolver_match = resolver.resolve(request.path_info)
  File "/usr/local/lib/python2.7/dist-packages/Django-1.7.7-py2.7.egg/django/core/urlresolvers.py", line 345, in resolve
    sub_match = pattern.resolve(new_path)
  File "/usr/local/lib/python2.7/dist-packages/Django-1.7.7-py2.7.egg/django/core/urlresolvers.py", line 345, in resolve
    sub_match = pattern.resolve(new_path)
  File "/usr/local/lib/python2.7/dist-packages/Django-1.7.7-py2.7.egg/django/core/urlresolvers.py", line 224, in resolve
    return ResolverMatch(self.callback, args, kwargs, self.name)
  File "/usr/local/lib/python2.7/dist-packages/Django-1.7.7-py2.7.egg/django/core/urlresolvers.py", line 231, in callback
    self._callback = get_callable(self._callback_str)
  File "/usr/local/lib/python2.7/dist-packages/Django-1.7.7-py2.7.egg/django/utils/lru_cache.py", line 101, in wrapper
    result = user_function(*args, **kwds)
  File "/usr/local/lib/python2.7/dist-packages/Django-1.7.7-py2.7.egg/django/core/urlresolvers.py", line 97, in get_callable
    mod = import_module(mod_name)
  File "/usr/lib/python2.7/importlib/__init__.py", line 37, in import_module
    __import__(name)
  File "/home/jing/python_app/tiaozy/application/display_items/views.py", line 20
    if request.method == "POST"
                              ^
SyntaxError: invalid syntax
[2015-04-19 12:23:11,405] [django.request] [ERROR] Internal Server Error: /post-item/
Traceback (most recent call last):
  File "/usr/local/lib/python2.7/dist-packages/Django-1.7.7-py2.7.egg/django/core/handlers/base.py", line 98, in get_response
    resolver_match = resolver.resolve(request.path_info)
  File "/usr/local/lib/python2.7/dist-packages/Django-1.7.7-py2.7.egg/django/core/urlresolvers.py", line 345, in resolve
    sub_match = pattern.resolve(new_path)
  File "/usr/local/lib/python2.7/dist-packages/Django-1.7.7-py2.7.egg/django/core/urlresolvers.py", line 345, in resolve
    sub_match = pattern.resolve(new_path)
  File "/usr/local/lib/python2.7/dist-packages/Django-1.7.7-py2.7.egg/django/core/urlresolvers.py", line 224, in resolve
    return ResolverMatch(self.callback, args, kwargs, self.name)
  File "/usr/local/lib/python2.7/dist-packages/Django-1.7.7-py2.7.egg/django/core/urlresolvers.py", line 231, in callback
    self._callback = get_callable(self._callback_str)
  File "/usr/local/lib/python2.7/dist-packages/Django-1.7.7-py2.7.egg/django/utils/lru_cache.py", line 101, in wrapper
    result = user_function(*args, **kwds)
  File "/usr/local/lib/python2.7/dist-packages/Django-1.7.7-py2.7.egg/django/core/urlresolvers.py", line 97, in get_callable
    mod = import_module(mod_name)
  File "/usr/lib/python2.7/importlib/__init__.py", line 37, in import_module
    __import__(name)
  File "/home/jing/python_app/tiaozy/application/display_items/views.py", line 23
    except Exception as e:
   ^
IndentationError: expected an indented block
[2015-04-19 13:51:26,374] [django.request] [ERROR] Internal Server Error: /publish-item/
Traceback (most recent call last):
  File "/usr/local/lib/python2.7/dist-packages/Django-1.7.7-py2.7.egg/django/core/handlers/base.py", line 98, in get_response
    resolver_match = resolver.resolve(request.path_info)
  File "/usr/local/lib/python2.7/dist-packages/Django-1.7.7-py2.7.egg/django/core/urlresolvers.py", line 345, in resolve
    sub_match = pattern.resolve(new_path)
  File "/usr/local/lib/python2.7/dist-packages/Django-1.7.7-py2.7.egg/django/core/urlresolvers.py", line 345, in resolve
    sub_match = pattern.resolve(new_path)
  File "/usr/local/lib/python2.7/dist-packages/Django-1.7.7-py2.7.egg/django/core/urlresolvers.py", line 224, in resolve
    return ResolverMatch(self.callback, args, kwargs, self.name)
  File "/usr/local/lib/python2.7/dist-packages/Django-1.7.7-py2.7.egg/django/core/urlresolvers.py", line 231, in callback
    self._callback = get_callable(self._callback_str)
  File "/usr/local/lib/python2.7/dist-packages/Django-1.7.7-py2.7.egg/django/utils/lru_cache.py", line 101, in wrapper
    result = user_function(*args, **kwds)
  File "/usr/local/lib/python2.7/dist-packages/Django-1.7.7-py2.7.egg/django/core/urlresolvers.py", line 97, in get_callable
    mod = import_module(mod_name)
  File "/usr/lib/python2.7/importlib/__init__.py", line 37, in import_module
    __import__(name)
  File "/home/jing/python_app/tiaozy/application/html_files/views.py", line 28
    print typeIndex
        ^
SyntaxError: invalid syntax
[2015-04-19 13:52:48,688] [django.request] [ERROR] Internal Server Error: /publish-item/pub/
Traceback (most recent call last):
  File "/usr/local/lib/python2.7/dist-packages/Django-1.7.7-py2.7.egg/django/core/handlers/base.py", line 111, in get_response
    response = wrapped_callback(request, *callback_args, **callback_kwargs)
  File "/home/jing/python_app/tiaozy/application/html_files/views.py", line 30, in pub_1
    print 'type: %i'%(typeIndex)
TypeError: %d format: a number is required, not unicode
[2015-04-19 14:37:25,439] [django.request] [ERROR] Internal Server Error: /post-item/
Traceback (most recent call last):
  File "/usr/local/lib/python2.7/dist-packages/Django-1.7.7-py2.7.egg/django/core/handlers/base.py", line 98, in get_response
    resolver_match = resolver.resolve(request.path_info)
  File "/usr/local/lib/python2.7/dist-packages/Django-1.7.7-py2.7.egg/django/core/urlresolvers.py", line 345, in resolve
    sub_match = pattern.resolve(new_path)
  File "/usr/local/lib/python2.7/dist-packages/Django-1.7.7-py2.7.egg/django/core/urlresolvers.py", line 345, in resolve
    sub_match = pattern.resolve(new_path)
  File "/usr/local/lib/python2.7/dist-packages/Django-1.7.7-py2.7.egg/django/core/urlresolvers.py", line 224, in resolve
    return ResolverMatch(self.callback, args, kwargs, self.name)
  File "/usr/local/lib/python2.7/dist-packages/Django-1.7.7-py2.7.egg/django/core/urlresolvers.py", line 231, in callback
    self._callback = get_callable(self._callback_str)
  File "/usr/local/lib/python2.7/dist-packages/Django-1.7.7-py2.7.egg/django/utils/lru_cache.py", line 101, in wrapper
    result = user_function(*args, **kwds)
  File "/usr/local/lib/python2.7/dist-packages/Django-1.7.7-py2.7.egg/django/core/urlresolvers.py", line 97, in get_callable
    mod = import_module(mod_name)
  File "/usr/lib/python2.7/importlib/__init__.py", line 37, in import_module
    __import__(name)
  File "/home/jing/python_app/tiaozy/application/display_items/views.py", line 36
    feature = request.POST.get('feature')=='1'?"全新":"非全新"
                                              ^
SyntaxError: invalid syntax
[2015-04-19 14:39:29,771] [django.request] [ERROR] Internal Server Error: /post-item/
Traceback (most recent call last):
  File "/usr/local/lib/python2.7/dist-packages/Django-1.7.7-py2.7.egg/django/core/handlers/base.py", line 98, in get_response
    resolver_match = resolver.resolve(request.path_info)
  File "/usr/local/lib/python2.7/dist-packages/Django-1.7.7-py2.7.egg/django/core/urlresolvers.py", line 345, in resolve
    sub_match = pattern.resolve(new_path)
  File "/usr/local/lib/python2.7/dist-packages/Django-1.7.7-py2.7.egg/django/core/urlresolvers.py", line 345, in resolve
    sub_match = pattern.resolve(new_path)
  File "/usr/local/lib/python2.7/dist-packages/Django-1.7.7-py2.7.egg/django/core/urlresolvers.py", line 224, in resolve
    return ResolverMatch(self.callback, args, kwargs, self.name)
  File "/usr/local/lib/python2.7/dist-packages/Django-1.7.7-py2.7.egg/django/core/urlresolvers.py", line 231, in callback
    self._callback = get_callable(self._callback_str)
  File "/usr/local/lib/python2.7/dist-packages/Django-1.7.7-py2.7.egg/django/utils/lru_cache.py", line 101, in wrapper
    result = user_function(*args, **kwds)
  File "/usr/local/lib/python2.7/dist-packages/Django-1.7.7-py2.7.egg/django/core/urlresolvers.py", line 97, in get_callable
    mod = import_module(mod_name)
  File "/usr/lib/python2.7/importlib/__init__.py", line 37, in import_module
    __import__(name)
  File "/home/jing/python_app/tiaozy/application/display_items/views.py", line 36
    feature = (request.POST.get('feature')=='1')?"全新":"非全新"
                                                ^
SyntaxError: invalid syntax
[2015-04-19 14:40:27,673] [django.request] [ERROR] Internal Server Error: /post-item/
Traceback (most recent call last):
  File "/usr/local/lib/python2.7/dist-packages/Django-1.7.7-py2.7.egg/django/core/handlers/base.py", line 98, in get_response
    resolver_match = resolver.resolve(request.path_info)
  File "/usr/local/lib/python2.7/dist-packages/Django-1.7.7-py2.7.egg/django/core/urlresolvers.py", line 345, in resolve
    sub_match = pattern.resolve(new_path)
  File "/usr/local/lib/python2.7/dist-packages/Django-1.7.7-py2.7.egg/django/core/urlresolvers.py", line 345, in resolve
    sub_match = pattern.resolve(new_path)
  File "/usr/local/lib/python2.7/dist-packages/Django-1.7.7-py2.7.egg/django/core/urlresolvers.py", line 224, in resolve
    return ResolverMatch(self.callback, args, kwargs, self.name)
  File "/usr/local/lib/python2.7/dist-packages/Django-1.7.7-py2.7.egg/django/core/urlresolvers.py", line 231, in callback
    self._callback = get_callable(self._callback_str)
  File "/usr/local/lib/python2.7/dist-packages/Django-1.7.7-py2.7.egg/django/utils/lru_cache.py", line 101, in wrapper
    result = user_function(*args, **kwds)
  File "/usr/local/lib/python2.7/dist-packages/Django-1.7.7-py2.7.egg/django/core/urlresolvers.py", line 97, in get_callable
    mod = import_module(mod_name)
  File "/usr/lib/python2.7/importlib/__init__.py", line 37, in import_module
    __import__(name)
  File "/home/jing/python_app/tiaozy/application/display_items/views.py", line 37
    feature = temp== '1'? "全新" : "非全新"
                        ^
SyntaxError: invalid syntax
[2015-04-19 14:40:58,880] [django.request] [ERROR] Internal Server Error: /post-item/
Traceback (most recent call last):
  File "/usr/local/lib/python2.7/dist-packages/Django-1.7.7-py2.7.egg/django/core/handlers/base.py", line 98, in get_response
    resolver_match = resolver.resolve(request.path_info)
  File "/usr/local/lib/python2.7/dist-packages/Django-1.7.7-py2.7.egg/django/core/urlresolvers.py", line 345, in resolve
    sub_match = pattern.resolve(new_path)
  File "/usr/local/lib/python2.7/dist-packages/Django-1.7.7-py2.7.egg/django/core/urlresolvers.py", line 345, in resolve
    sub_match = pattern.resolve(new_path)
  File "/usr/local/lib/python2.7/dist-packages/Django-1.7.7-py2.7.egg/django/core/urlresolvers.py", line 224, in resolve
    return ResolverMatch(self.callback, args, kwargs, self.name)
  File "/usr/local/lib/python2.7/dist-packages/Django-1.7.7-py2.7.egg/django/core/urlresolvers.py", line 231, in callback
    self._callback = get_callable(self._callback_str)
  File "/usr/local/lib/python2.7/dist-packages/Django-1.7.7-py2.7.egg/django/utils/lru_cache.py", line 101, in wrapper
    result = user_function(*args, **kwds)
  File "/usr/local/lib/python2.7/dist-packages/Django-1.7.7-py2.7.egg/django/core/urlresolvers.py", line 97, in get_callable
    mod = import_module(mod_name)
  File "/usr/lib/python2.7/importlib/__init__.py", line 37, in import_module
    __import__(name)
  File "/home/jing/python_app/tiaozy/application/display_items/views.py", line 38
    feature = (temp== '1'? "全新" : "非全新")
                         ^
SyntaxError: invalid syntax
[2015-04-19 14:41:30,338] [django.request] [ERROR] Internal Server Error: /post-item/
Traceback (most recent call last):
  File "/usr/local/lib/python2.7/dist-packages/Django-1.7.7-py2.7.egg/django/core/handlers/base.py", line 98, in get_response
    resolver_match = resolver.resolve(request.path_info)
  File "/usr/local/lib/python2.7/dist-packages/Django-1.7.7-py2.7.egg/django/core/urlresolvers.py", line 345, in resolve
    sub_match = pattern.resolve(new_path)
  File "/usr/local/lib/python2.7/dist-packages/Django-1.7.7-py2.7.egg/django/core/urlresolvers.py", line 345, in resolve
    sub_match = pattern.resolve(new_path)
  File "/usr/local/lib/python2.7/dist-packages/Django-1.7.7-py2.7.egg/django/core/urlresolvers.py", line 224, in resolve
    return ResolverMatch(self.callback, args, kwargs, self.name)
  File "/usr/local/lib/python2.7/dist-packages/Django-1.7.7-py2.7.egg/django/core/urlresolvers.py", line 231, in callback
    self._callback = get_callable(self._callback_str)
  File "/usr/local/lib/python2.7/dist-packages/Django-1.7.7-py2.7.egg/django/utils/lru_cache.py", line 101, in wrapper
    result = user_function(*args, **kwds)
  File "/usr/local/lib/python2.7/dist-packages/Django-1.7.7-py2.7.egg/django/core/urlresolvers.py", line 97, in get_callable
    mod = import_module(mod_name)
  File "/usr/lib/python2.7/importlib/__init__.py", line 37, in import_module
    __import__(name)
  File "/home/jing/python_app/tiaozy/application/display_items/views.py", line 38
    feature = (temp== '1'? "全新" : "非全新")
                         ^
SyntaxError: invalid syntax
[2015-04-19 14:41:51,956] [django.request] [ERROR] Internal Server Error: /post-item/
Traceback (most recent call last):
  File "/usr/local/lib/python2.7/dist-packages/Django-1.7.7-py2.7.egg/django/core/handlers/base.py", line 98, in get_response
    resolver_match = resolver.resolve(request.path_info)
  File "/usr/local/lib/python2.7/dist-packages/Django-1.7.7-py2.7.egg/django/core/urlresolvers.py", line 345, in resolve
    sub_match = pattern.resolve(new_path)
  File "/usr/local/lib/python2.7/dist-packages/Django-1.7.7-py2.7.egg/django/core/urlresolvers.py", line 345, in resolve
    sub_match = pattern.resolve(new_path)
  File "/usr/local/lib/python2.7/dist-packages/Django-1.7.7-py2.7.egg/django/core/urlresolvers.py", line 224, in resolve
    return ResolverMatch(self.callback, args, kwargs, self.name)
  File "/usr/local/lib/python2.7/dist-packages/Django-1.7.7-py2.7.egg/django/core/urlresolvers.py", line 231, in callback
    self._callback = get_callable(self._callback_str)
  File "/usr/local/lib/python2.7/dist-packages/Django-1.7.7-py2.7.egg/django/utils/lru_cache.py", line 101, in wrapper
    result = user_function(*args, **kwds)
  File "/usr/local/lib/python2.7/dist-packages/Django-1.7.7-py2.7.egg/django/core/urlresolvers.py", line 97, in get_callable
    mod = import_module(mod_name)
  File "/usr/lib/python2.7/importlib/__init__.py", line 37, in import_module
    __import__(name)
  File "/home/jing/python_app/tiaozy/application/display_items/views.py", line 9, in <module>
    from application.ssl_users import user_items_table
ImportError: cannot import name user_items_table
[2015-04-19 15:30:23,123] [django.request] [ERROR] Internal Server Error: /post-item/
Traceback (most recent call last):
  File "/usr/local/lib/python2.7/dist-packages/Django-1.7.7-py2.7.egg/django/core/handlers/base.py", line 98, in get_response
    resolver_match = resolver.resolve(request.path_info)
  File "/usr/local/lib/python2.7/dist-packages/Django-1.7.7-py2.7.egg/django/core/urlresolvers.py", line 345, in resolve
    sub_match = pattern.resolve(new_path)
  File "/usr/local/lib/python2.7/dist-packages/Django-1.7.7-py2.7.egg/django/core/urlresolvers.py", line 345, in resolve
    sub_match = pattern.resolve(new_path)
  File "/usr/local/lib/python2.7/dist-packages/Django-1.7.7-py2.7.egg/django/core/urlresolvers.py", line 224, in resolve
    return ResolverMatch(self.callback, args, kwargs, self.name)
  File "/usr/local/lib/python2.7/dist-packages/Django-1.7.7-py2.7.egg/django/core/urlresolvers.py", line 231, in callback
    self._callback = get_callable(self._callback_str)
  File "/usr/local/lib/python2.7/dist-packages/Django-1.7.7-py2.7.egg/django/utils/lru_cache.py", line 101, in wrapper
    result = user_function(*args, **kwds)
  File "/usr/local/lib/python2.7/dist-packages/Django-1.7.7-py2.7.egg/django/core/urlresolvers.py", line 97, in get_callable
    mod = import_module(mod_name)
  File "/usr/lib/python2.7/importlib/__init__.py", line 37, in import_module
    __import__(name)
  File "/home/jing/python_app/tiaozy/application/display_items/views.py", line 37
    feature = (temp== '1'? "全新" : "非全新")
                         ^
SyntaxError: invalid syntax
[2015-04-20 02:53:43,973] [django.request] [ERROR] Internal Server Error: /post-item/
Traceback (most recent call last):
  File "/usr/local/lib/python2.7/dist-packages/django/core/handlers/base.py", line 98, in get_response
    resolver_match = resolver.resolve(request.path_info)
  File "/usr/local/lib/python2.7/dist-packages/django/core/urlresolvers.py", line 345, in resolve
    sub_match = pattern.resolve(new_path)
  File "/usr/local/lib/python2.7/dist-packages/django/core/urlresolvers.py", line 345, in resolve
    sub_match = pattern.resolve(new_path)
  File "/usr/local/lib/python2.7/dist-packages/django/core/urlresolvers.py", line 224, in resolve
    return ResolverMatch(self.callback, args, kwargs, self.name)
  File "/usr/local/lib/python2.7/dist-packages/django/core/urlresolvers.py", line 231, in callback
    self._callback = get_callable(self._callback_str)
  File "/usr/local/lib/python2.7/dist-packages/django/utils/lru_cache.py", line 101, in wrapper
    result = user_function(*args, **kwds)
  File "/usr/local/lib/python2.7/dist-packages/django/core/urlresolvers.py", line 97, in get_callable
    mod = import_module(mod_name)
  File "/usr/lib/python2.7/importlib/__init__.py", line 37, in import_module
    __import__(name)
  File "/home/jing/tiaozy/application/display_items/views.py", line 3, in <module>
    from oss.oss_api import *
ImportError: No module named oss.oss_api
[2015-04-20 03:30:33,386] [django.request] [ERROR] Internal Server Error: /post-item/
Traceback (most recent call last):
  File "/usr/local/lib/python2.7/dist-packages/django/core/handlers/base.py", line 98, in get_response
    resolver_match = resolver.resolve(request.path_info)
  File "/usr/local/lib/python2.7/dist-packages/django/core/urlresolvers.py", line 345, in resolve
    sub_match = pattern.resolve(new_path)
  File "/usr/local/lib/python2.7/dist-packages/django/core/urlresolvers.py", line 345, in resolve
    sub_match = pattern.resolve(new_path)
  File "/usr/local/lib/python2.7/dist-packages/django/core/urlresolvers.py", line 224, in resolve
    return ResolverMatch(self.callback, args, kwargs, self.name)
  File "/usr/local/lib/python2.7/dist-packages/django/core/urlresolvers.py", line 231, in callback
    self._callback = get_callable(self._callback_str)
  File "/usr/local/lib/python2.7/dist-packages/django/utils/lru_cache.py", line 101, in wrapper
    result = user_function(*args, **kwds)
  File "/usr/local/lib/python2.7/dist-packages/django/core/urlresolvers.py", line 97, in get_callable
    mod = import_module(mod_name)
  File "/usr/lib/python2.7/importlib/__init__.py", line 37, in import_module
    __import__(name)
  File "/home/jing/tiaozy/application/display_items/views.py", line 21
    if not request.user,is_authenticated():
                       ^
SyntaxError: invalid syntax
[2015-04-20 03:31:46,895] [django.request] [ERROR] Internal Server Error: /post-item/
Traceback (most recent call last):
  File "/usr/local/lib/python2.7/dist-packages/django/core/handlers/base.py", line 204, in get_response
    response = middleware_method(request, response)
  File "/usr/local/lib/python2.7/dist-packages/django/middleware/clickjacking.py", line 31, in process_response
    if response.get('X-Frame-Options', None) is not None:
AttributeError: 'str' object has no attribute 'get'
[2015-04-20 03:32:42,941] [django.request] [ERROR] Internal Server Error: /post-item/
Traceback (most recent call last):
  File "/usr/local/lib/python2.7/dist-packages/django/core/handlers/base.py", line 204, in get_response
    response = middleware_method(request, response)
  File "/usr/local/lib/python2.7/dist-packages/django/middleware/clickjacking.py", line 31, in process_response
    if response.get('X-Frame-Options', None) is not None:
AttributeError: 'str' object has no attribute 'get'
[2015-04-20 04:21:05,042] [django.request] [ERROR] Internal Server Error: /post-ask-info/
Traceback (most recent call last):
  File "/usr/local/lib/python2.7/dist-packages/django/core/handlers/base.py", line 98, in get_response
    resolver_match = resolver.resolve(request.path_info)
  File "/usr/local/lib/python2.7/dist-packages/django/core/urlresolvers.py", line 345, in resolve
    sub_match = pattern.resolve(new_path)
  File "/usr/local/lib/python2.7/dist-packages/django/core/urlresolvers.py", line 345, in resolve
    sub_match = pattern.resolve(new_path)
  File "/usr/local/lib/python2.7/dist-packages/django/core/urlresolvers.py", line 224, in resolve
    return ResolverMatch(self.callback, args, kwargs, self.name)
  File "/usr/local/lib/python2.7/dist-packages/django/core/urlresolvers.py", line 231, in callback
    self._callback = get_callable(self._callback_str)
  File "/usr/local/lib/python2.7/dist-packages/django/utils/lru_cache.py", line 101, in wrapper
    result = user_function(*args, **kwds)
  File "/usr/local/lib/python2.7/dist-packages/django/core/urlresolvers.py", line 97, in get_callable
    mod = import_module(mod_name)
  File "/usr/lib/python2.7/importlib/__init__.py", line 37, in import_module
    __import__(name)
  File "/home/jing/tiaozy/application/display_items/views.py", line 11, in <module>
    from application.display_items.models import ask_info_table
  File "/home/jing/tiaozy/application/display_items/models.py", line 20
    @classmethod
    ^
IndentationError: unexpected indent
[2015-04-20 04:21:31,423] [django.request] [ERROR] Internal Server Error: /post-ask-info/
Traceback (most recent call last):
  File "/usr/local/lib/python2.7/dist-packages/django/core/handlers/base.py", line 98, in get_response
    resolver_match = resolver.resolve(request.path_info)
  File "/usr/local/lib/python2.7/dist-packages/django/core/urlresolvers.py", line 345, in resolve
    sub_match = pattern.resolve(new_path)
  File "/usr/local/lib/python2.7/dist-packages/django/core/urlresolvers.py", line 345, in resolve
    sub_match = pattern.resolve(new_path)
  File "/usr/local/lib/python2.7/dist-packages/django/core/urlresolvers.py", line 224, in resolve
    return ResolverMatch(self.callback, args, kwargs, self.name)
  File "/usr/local/lib/python2.7/dist-packages/django/core/urlresolvers.py", line 231, in callback
    self._callback = get_callable(self._callback_str)
  File "/usr/local/lib/python2.7/dist-packages/django/utils/lru_cache.py", line 101, in wrapper
    result = user_function(*args, **kwds)
  File "/usr/local/lib/python2.7/dist-packages/django/core/urlresolvers.py", line 97, in get_callable
    mod = import_module(mod_name)
  File "/usr/lib/python2.7/importlib/__init__.py", line 37, in import_module
    __import__(name)
  File "/home/jing/tiaozy/application/display_items/views.py", line 11, in <module>
    from application.display_items.models import ask_info_table
  File "/home/jing/tiaozy/application/display_items/models.py", line 4, in <module>
    class ask_info_table(models.Model):
  File "/home/jing/tiaozy/application/display_items/models.py", line 13, in ask_info_table
    TzyUser        = models.ForeignKey(tzy_users)
NameError: name 'tzy_users' is not defined
[2015-04-20 05:40:40,296] [django.request] [ERROR] Internal Server Error: /
Traceback (most recent call last):
  File "/usr/local/lib/python2.7/dist-packages/django/core/handlers/base.py", line 98, in get_response
    resolver_match = resolver.resolve(request.path_info)
  File "/usr/local/lib/python2.7/dist-packages/django/core/urlresolvers.py", line 343, in resolve
    for pattern in self.url_patterns:
  File "/usr/local/lib/python2.7/dist-packages/django/core/urlresolvers.py", line 372, in url_patterns
    patterns = getattr(self.urlconf_module, "urlpatterns", self.urlconf_module)
  File "/usr/local/lib/python2.7/dist-packages/django/core/urlresolvers.py", line 366, in urlconf_module
    self._urlconf_module = import_module(self.urlconf_name)
  File "/usr/lib/python2.7/importlib/__init__.py", line 37, in import_module
    __import__(name)
ImportError: No module named urls
[2015-04-20 07:00:30,117] [django.request] [ERROR] Internal Server Error: /get-on-selling
Traceback (most recent call last):
  File "/usr/local/lib/python2.7/dist-packages/django/core/handlers/base.py", line 87, in get_response
    response = middleware_method(request)
  File "/usr/local/lib/python2.7/dist-packages/django/middleware/common.py", line 72, in process_request
    if (not urlresolvers.is_valid_path(request.path_info, urlconf) and
  File "/usr/local/lib/python2.7/dist-packages/django/core/urlresolvers.py", line 619, in is_valid_path
    resolve(path, urlconf)
  File "/usr/local/lib/python2.7/dist-packages/django/core/urlresolvers.py", line 494, in resolve
    return get_resolver(urlconf).resolve(path)
  File "/usr/local/lib/python2.7/dist-packages/django/core/urlresolvers.py", line 345, in resolve
    sub_match = pattern.resolve(new_path)
  File "/usr/local/lib/python2.7/dist-packages/django/core/urlresolvers.py", line 345, in resolve
    sub_match = pattern.resolve(new_path)
  File "/usr/local/lib/python2.7/dist-packages/django/core/urlresolvers.py", line 224, in resolve
    return ResolverMatch(self.callback, args, kwargs, self.name)
  File "/usr/local/lib/python2.7/dist-packages/django/core/urlresolvers.py", line 231, in callback
    self._callback = get_callable(self._callback_str)
  File "/usr/local/lib/python2.7/dist-packages/django/utils/lru_cache.py", line 101, in wrapper
    result = user_function(*args, **kwds)
  File "/usr/local/lib/python2.7/dist-packages/django/core/urlresolvers.py", line 97, in get_callable
    mod = import_module(mod_name)
  File "/usr/lib/python2.7/importlib/__init__.py", line 37, in import_module
    __import__(name)
  File "/home/jing/python_server/tiaozy/application/display_items/views.py", line 139
    "ImageUrl":item.ItemImageUrls.0,
                                  ^
SyntaxError: invalid syntax
[2015-04-20 07:00:45,079] [django.request] [ERROR] Internal Server Error: /get-on-selling
Traceback (most recent call last):
  File "/usr/local/lib/python2.7/dist-packages/django/core/handlers/base.py", line 87, in get_response
    response = middleware_method(request)
  File "/usr/local/lib/python2.7/dist-packages/django/middleware/common.py", line 72, in process_request
    if (not urlresolvers.is_valid_path(request.path_info, urlconf) and
  File "/usr/local/lib/python2.7/dist-packages/django/core/urlresolvers.py", line 619, in is_valid_path
    resolve(path, urlconf)
  File "/usr/local/lib/python2.7/dist-packages/django/core/urlresolvers.py", line 494, in resolve
    return get_resolver(urlconf).resolve(path)
  File "/usr/local/lib/python2.7/dist-packages/django/core/urlresolvers.py", line 345, in resolve
    sub_match = pattern.resolve(new_path)
  File "/usr/local/lib/python2.7/dist-packages/django/core/urlresolvers.py", line 345, in resolve
    sub_match = pattern.resolve(new_path)
  File "/usr/local/lib/python2.7/dist-packages/django/core/urlresolvers.py", line 224, in resolve
    return ResolverMatch(self.callback, args, kwargs, self.name)
  File "/usr/local/lib/python2.7/dist-packages/django/core/urlresolvers.py", line 231, in callback
    self._callback = get_callable(self._callback_str)
  File "/usr/local/lib/python2.7/dist-packages/django/utils/lru_cache.py", line 101, in wrapper
    result = user_function(*args, **kwds)
  File "/usr/local/lib/python2.7/dist-packages/django/core/urlresolvers.py", line 97, in get_callable
    mod = import_module(mod_name)
  File "/usr/lib/python2.7/importlib/__init__.py", line 37, in import_module
    __import__(name)
  File "/home/jing/python_server/tiaozy/application/display_items/views.py", line 139
    "ImageUrl":item.ItemImageUrls.0,
                                  ^
SyntaxError: invalid syntax
[2015-04-19 16:20:15,738] [django.request] [ERROR] Internal Server Error: /
Traceback (most recent call last):
  File "/usr/local/lib/python2.7/dist-packages/Django-1.7.7-py2.7.egg/django/core/handlers/base.py", line 98, in get_response
    resolver_match = resolver.resolve(request.path_info)
  File "/usr/local/lib/python2.7/dist-packages/Django-1.7.7-py2.7.egg/django/core/urlresolvers.py", line 345, in resolve
    sub_match = pattern.resolve(new_path)
  File "/usr/local/lib/python2.7/dist-packages/Django-1.7.7-py2.7.egg/django/core/urlresolvers.py", line 224, in resolve
    return ResolverMatch(self.callback, args, kwargs, self.name)
  File "/usr/local/lib/python2.7/dist-packages/Django-1.7.7-py2.7.egg/django/core/urlresolvers.py", line 231, in callback
    self._callback = get_callable(self._callback_str)
  File "/usr/local/lib/python2.7/dist-packages/Django-1.7.7-py2.7.egg/django/utils/lru_cache.py", line 101, in wrapper
    result = user_function(*args, **kwds)
  File "/usr/local/lib/python2.7/dist-packages/Django-1.7.7-py2.7.egg/django/core/urlresolvers.py", line 97, in get_callable
    mod = import_module(mod_name)
  File "/usr/lib/python2.7/importlib/__init__.py", line 37, in import_module
    __import__(name)
  File "/home/jing/python_app/tiaozy/application/html_files/views.py", line 6, in <module>
    from application.ssl_users import tzy_users
ImportError: cannot import name tzy_users
[2015-04-21 02:22:25,925] [django.request] [ERROR] Internal Server Error: /publish/
Traceback (most recent call last):
  File "/usr/local/lib/python2.7/dist-packages/django/core/handlers/base.py", line 98, in get_response
    resolver_match = resolver.resolve(request.path_info)
  File "/usr/local/lib/python2.7/dist-packages/django/core/urlresolvers.py", line 345, in resolve
    sub_match = pattern.resolve(new_path)
  File "/usr/local/lib/python2.7/dist-packages/django/core/urlresolvers.py", line 345, in resolve
    sub_match = pattern.resolve(new_path)
  File "/usr/local/lib/python2.7/dist-packages/django/core/urlresolvers.py", line 224, in resolve
    return ResolverMatch(self.callback, args, kwargs, self.name)
  File "/usr/local/lib/python2.7/dist-packages/django/core/urlresolvers.py", line 231, in callback
    self._callback = get_callable(self._callback_str)
  File "/usr/local/lib/python2.7/dist-packages/django/utils/lru_cache.py", line 101, in wrapper
    result = user_function(*args, **kwds)
  File "/usr/local/lib/python2.7/dist-packages/django/core/urlresolvers.py", line 97, in get_callable
    mod = import_module(mod_name)
  File "/usr/lib/python2.7/importlib/__init__.py", line 37, in import_module
    __import__(name)
  File "/home/jing/python_server/tiaozy/application/html_files/views.py", line 9, in <module>
    from application.config.globals import *
  File "/home/jing/python_server/tiaozy/application/config/globals.py", line 43
    ["箱包","其他"] ];
                        ^
SyntaxError: invalid syntax
[2015-04-21 03:39:49,226] [django.request] [ERROR] Internal Server Error: /
Traceback (most recent call last):
  File "/usr/local/lib/python2.7/dist-packages/django/core/handlers/base.py", line 111, in get_response
    response = wrapped_callback(request, *callback_args, **callback_kwargs)
  File "/home/jing/python_server/tiaozy/application/html_files/views.py", line 15, in index
    hot_sets = user_items_table.objects.filter(username="尚书林").order_by('-ClickCount','-PostTime')[:4]
  File "/usr/local/lib/python2.7/dist-packages/django/db/models/manager.py", line 92, in manager_method
    return getattr(self.get_queryset(), name)(*args, **kwargs)
  File "/usr/local/lib/python2.7/dist-packages/django/db/models/query.py", line 691, in filter
    return self._filter_or_exclude(False, *args, **kwargs)
  File "/usr/local/lib/python2.7/dist-packages/django/db/models/query.py", line 709, in _filter_or_exclude
    clone.query.add_q(Q(*args, **kwargs))
  File "/usr/local/lib/python2.7/dist-packages/django/db/models/sql/query.py", line 1331, in add_q
    clause, require_inner = self._add_q(where_part, self.used_aliases)
  File "/usr/local/lib/python2.7/dist-packages/django/db/models/sql/query.py", line 1358, in _add_q
    current_negated=current_negated, connector=connector)
  File "/usr/local/lib/python2.7/dist-packages/django/db/models/sql/query.py", line 1182, in build_filter
    lookups, parts, reffed_aggregate = self.solve_lookup_type(arg)
  File "/usr/local/lib/python2.7/dist-packages/django/db/models/sql/query.py", line 1120, in solve_lookup_type
    _, field, _, lookup_parts = self.names_to_path(lookup_splitted, self.get_meta())
  File "/usr/local/lib/python2.7/dist-packages/django/db/models/sql/query.py", line 1427, in names_to_path
    self.raise_field_error(opts, name)
  File "/usr/local/lib/python2.7/dist-packages/django/db/models/sql/query.py", line 1433, in raise_field_error
    "Choices are: %s" % (name, ", ".join(available)))
FieldError: Cannot resolve keyword 'username' into field. Choices are: ClickCount, ContactUserName, ContactUserPhone, Feature, IsBlock, ItemDescription, ItemId, ItemImageUrls, ItemName, ItemOldPrice, ItemPrice, ItemType, ItemsNum, LastEditTime, LikeCount, LikeList, PostTime, ReportList, ReportReason, TzyUser, TzyUser_id, id
[2015-04-21 03:44:50,126] [django.request] [ERROR] Internal Server Error: /
Traceback (most recent call last):
  File "/usr/local/lib/python2.7/dist-packages/django/core/handlers/base.py", line 111, in get_response
    response = wrapped_callback(request, *callback_args, **callback_kwargs)
  File "/home/jing/python_server/tiaozy/application/html_files/views.py", line 20, in index
    image_urls = json.loads(item.ItemImageUrls)
NameError: global name 'json' is not defined
[2015-04-21 03:57:39,723] [django.request] [ERROR] Internal Server Error: /
Traceback (most recent call last):
  File "/usr/local/lib/python2.7/dist-packages/django/core/handlers/base.py", line 98, in get_response
    resolver_match = resolver.resolve(request.path_info)
  File "/usr/local/lib/python2.7/dist-packages/django/core/urlresolvers.py", line 345, in resolve
    sub_match = pattern.resolve(new_path)
  File "/usr/local/lib/python2.7/dist-packages/django/core/urlresolvers.py", line 224, in resolve
    return ResolverMatch(self.callback, args, kwargs, self.name)
  File "/usr/local/lib/python2.7/dist-packages/django/core/urlresolvers.py", line 231, in callback
    self._callback = get_callable(self._callback_str)
  File "/usr/local/lib/python2.7/dist-packages/django/utils/lru_cache.py", line 101, in wrapper
    result = user_function(*args, **kwds)
  File "/usr/local/lib/python2.7/dist-packages/django/core/urlresolvers.py", line 97, in get_callable
    mod = import_module(mod_name)
  File "/usr/lib/python2.7/importlib/__init__.py", line 37, in import_module
    __import__(name)
  File "/home/jing/python_server/tiaozy/application/html_files/views.py", line 35
    en_sets = user_items_table.objects.filter(TzyUser=user_ssl,ItemType>='100',ItemType<"200").order_by('-ClickCount','-PostTime')[:6]
SyntaxError: non-keyword arg after keyword arg
[2015-04-21 04:15:02,189] [django.request] [ERROR] Internal Server Error: /
Traceback (most recent call last):
  File "/usr/local/lib/python2.7/dist-packages/django/core/handlers/base.py", line 111, in get_response
    response = wrapped_callback(request, *callback_args, **callback_kwargs)
  File "/home/jing/python_server/tiaozy/application/html_files/views.py", line 35, in index
    en_sets = user_items_table.objects.filter(TzyUser=user_ssl).filter(is_en_books).order_by('-ClickCount','-PostTime')[:6]
  File "/usr/local/lib/python2.7/dist-packages/django/db/models/query.py", line 691, in filter
    return self._filter_or_exclude(False, *args, **kwargs)
  File "/usr/local/lib/python2.7/dist-packages/django/db/models/query.py", line 709, in _filter_or_exclude
    clone.query.add_q(Q(*args, **kwargs))
  File "/usr/local/lib/python2.7/dist-packages/django/db/models/sql/query.py", line 1331, in add_q
    clause, require_inner = self._add_q(where_part, self.used_aliases)
  File "/usr/local/lib/python2.7/dist-packages/django/db/models/sql/query.py", line 1358, in _add_q
    current_negated=current_negated, connector=connector)
  File "/usr/local/lib/python2.7/dist-packages/django/db/models/sql/query.py", line 1179, in build_filter
    arg, value = filter_expr
TypeError: 'function' object is not iterable
