2015-03-11 10:35:00,427 [django.request:226] [ERROR]- Internal Server Error: /_/launch
Traceback (most recent call last):
  File "/usr/local/lib/python2.7/dist-packages/django/core/handlers/base.py", line 90, in get_response
    response = middleware_method(request)
  File "/usr/local/lib/python2.7/dist-packages/django/middleware/common.py", line 71, in process_request
    if (not urlresolvers.is_valid_path(request.path_info, urlconf) and
  File "/usr/local/lib/python2.7/dist-packages/django/core/urlresolvers.py", line 573, in is_valid_path
    resolve(path, urlconf)
  File "/usr/local/lib/python2.7/dist-packages/django/core/urlresolvers.py", line 453, in resolve
    return get_resolver(urlconf).resolve(path)
  File "/usr/local/lib/python2.7/dist-packages/django/core/urlresolvers.py", line 320, in resolve
    sub_match = pattern.resolve(new_path)
  File "/usr/local/lib/python2.7/dist-packages/django/core/urlresolvers.py", line 320, in resolve
    sub_match = pattern.resolve(new_path)
  File "/usr/local/lib/python2.7/dist-packages/django/core/urlresolvers.py", line 222, in resolve
    return ResolverMatch(self.callback, args, kwargs, self.name)
  File "/usr/local/lib/python2.7/dist-packages/django/core/urlresolvers.py", line 229, in callback
    self._callback = get_callable(self._callback_str)
  File "/usr/local/lib/python2.7/dist-packages/django/utils/functional.py", line 32, in wrapper
    result = func(*args)
  File "/usr/local/lib/python2.7/dist-packages/django/core/urlresolvers.py", line 96, in get_callable
    mod = import_module(mod_name)
  File "/usr/local/lib/python2.7/dist-packages/django/utils/importlib.py", line 40, in import_module
    __import__(name)
  File "/home/cheng-shiwen/Project/kuaiwen_server/application/user/views.py", line 33
    except Exception as e:
         ^
SyntaxError: invalid syntax
2015-03-11 10:35:45,781 [django.request:226] [ERROR]- Internal Server Error: /admin/
Traceback (most recent call last):
  File "/usr/local/lib/python2.7/dist-packages/django/core/handlers/base.py", line 114, in get_response
    response = wrapped_callback(request, *callback_args, **callback_kwargs)
  File "/usr/local/lib/python2.7/dist-packages/django/contrib/admin/sites.py", line 215, in wrapper
    return self.admin_view(view, cacheable)(*args, **kwargs)
  File "/usr/local/lib/python2.7/dist-packages/django/utils/decorators.py", line 99, in _wrapped_view
    response = view_func(request, *args, **kwargs)
  File "/usr/local/lib/python2.7/dist-packages/django/views/decorators/cache.py", line 52, in _wrapped_view_func
    response = view_func(request, *args, **kwargs)
  File "/usr/local/lib/python2.7/dist-packages/django/contrib/admin/sites.py", line 194, in inner
    current_app=self.name):
  File "/usr/local/lib/python2.7/dist-packages/django/core/urlresolvers.py", line 480, in reverse
    app_list = resolver.app_dict[ns]
  File "/usr/local/lib/python2.7/dist-packages/django/core/urlresolvers.py", line 310, in app_dict
    self._populate()
  File "/usr/local/lib/python2.7/dist-packages/django/core/urlresolvers.py", line 273, in _populate
    for name in pattern.reverse_dict:
  File "/usr/local/lib/python2.7/dist-packages/django/core/urlresolvers.py", line 296, in reverse_dict
    self._populate()
  File "/usr/local/lib/python2.7/dist-packages/django/core/urlresolvers.py", line 285, in _populate
    lookups.appendlist(pattern.callback, (bits, p_pattern, pattern.default_args))
  File "/usr/local/lib/python2.7/dist-packages/django/core/urlresolvers.py", line 229, in callback
    self._callback = get_callable(self._callback_str)
  File "/usr/local/lib/python2.7/dist-packages/django/utils/functional.py", line 32, in wrapper
    result = func(*args)
  File "/usr/local/lib/python2.7/dist-packages/django/core/urlresolvers.py", line 100, in get_callable
    not module_has_submodule(import_module(parentmod), submod)):
  File "/usr/local/lib/python2.7/dist-packages/django/utils/importlib.py", line 40, in import_module
    __import__(name)
ImportError: No module named comment
2015-03-11 10:51:38,722 [django.request:226] [ERROR]- Internal Server Error: /_/open-question
Traceback (most recent call last):
  File "/usr/local/lib/python2.7/dist-packages/django/core/handlers/base.py", line 114, in get_response
    response = wrapped_callback(request, *callback_args, **callback_kwargs)
  File "/home/cheng-shiwen/Project/kuaiwen_server/application/question/views.py", line 117, in open_question
    return handle_response(result, '打开问题失败', logger, 811, e)
UnboundLocalError: local variable 'result' referenced before assignment
2015-03-27 10:47:21,428 [django.request] [WARNING]- Not Found: /
2015-03-27 10:50:29,432 [django.request] [ERROR]- Internal Server Error: /admin/user/secretuser/
Traceback (most recent call last):
  File "/usr/local/lib/python2.7/dist-packages/django/core/handlers/base.py", line 114, in get_response
    response = wrapped_callback(request, *callback_args, **callback_kwargs)
  File "/usr/local/lib/python2.7/dist-packages/django/contrib/admin/options.py", line 432, in wrapper
    return self.admin_site.admin_view(view)(*args, **kwargs)
  File "/usr/local/lib/python2.7/dist-packages/django/utils/decorators.py", line 99, in _wrapped_view
    response = view_func(request, *args, **kwargs)
  File "/usr/local/lib/python2.7/dist-packages/django/views/decorators/cache.py", line 52, in _wrapped_view_func
    response = view_func(request, *args, **kwargs)
  File "/usr/local/lib/python2.7/dist-packages/django/contrib/admin/sites.py", line 198, in inner
    return view(request, *args, **kwargs)
  File "/usr/local/lib/python2.7/dist-packages/django/utils/decorators.py", line 29, in _wrapper
    return bound_func(*args, **kwargs)
  File "/usr/local/lib/python2.7/dist-packages/django/utils/decorators.py", line 99, in _wrapped_view
    response = view_func(request, *args, **kwargs)
  File "/usr/local/lib/python2.7/dist-packages/django/utils/decorators.py", line 25, in bound_func
    return func(self, *args2, **kwargs2)
  File "/usr/local/lib/python2.7/dist-packages/django/contrib/admin/options.py", line 1411, in changelist_view
    'selection_note': _('0 of %(cnt)s selected') % {'cnt': len(cl.result_list)},
  File "/usr/local/lib/python2.7/dist-packages/django/db/models/query.py", line 77, in __len__
    self._fetch_all()
  File "/usr/local/lib/python2.7/dist-packages/django/db/models/query.py", line 854, in _fetch_all
    self._result_cache = list(self.iterator())
  File "/usr/local/lib/python2.7/dist-packages/django/db/models/query.py", line 220, in iterator
    for row in compiler.results_iter():
  File "/usr/local/lib/python2.7/dist-packages/django/db/models/sql/compiler.py", line 709, in results_iter
    for rows in self.execute_sql(MULTI):
  File "/usr/local/lib/python2.7/dist-packages/django/db/models/sql/compiler.py", line 782, in execute_sql
    cursor.execute(sql, params)
  File "/usr/local/lib/python2.7/dist-packages/django/db/backends/util.py", line 69, in execute
    return super(CursorDebugWrapper, self).execute(sql, params)
  File "/usr/local/lib/python2.7/dist-packages/django/db/backends/util.py", line 53, in execute
    return self.cursor.execute(sql, params)
  File "/usr/local/lib/python2.7/dist-packages/django/db/utils.py", line 99, in __exit__
    six.reraise(dj_exc_type, dj_exc_value, traceback)
  File "/usr/local/lib/python2.7/dist-packages/django/db/backends/util.py", line 53, in execute
    return self.cursor.execute(sql, params)
  File "/usr/local/lib/python2.7/dist-packages/django/db/backends/mysql/base.py", line 124, in execute
    return self.cursor.execute(query, args)
  File "/usr/local/lib/python2.7/dist-packages/MySQLdb/cursors.py", line 205, in execute
    self.errorhandler(self, exc, value)
  File "/usr/local/lib/python2.7/dist-packages/MySQLdb/connections.py", line 36, in defaulterrorhandler
    raise errorclass, errorvalue
OperationalError: (1054, "Unknown column 'user_secretuser.ClientIP' in 'field list'")
2015-03-27 15:29:43,946 [django.request] [WARNING]- Not Found: /_/report-question
[2015-03-27 18:29:07,882] [django.request] [ERROR] Internal Server Error: /_/report-question
Traceback (most recent call last):
  File "/usr/local/lib/python2.7/dist-packages/django/core/handlers/base.py", line 114, in get_response
    response = wrapped_callback(request, *callback_args, **callback_kwargs)
  File "/home/cheng-shiwen/Project/kuaiwen_server/application/question/views.py", line 228, in report_question
    return handle_response(result, '举报问题失败', logger, 811, e)
UnboundLocalError: local variable 'result' referenced before assignment
[2015-03-28 15:07:32,201] [django.request] [ERROR] Internal Server Error: /manage
Traceback (most recent call last):
  File "/usr/local/lib/python2.7/dist-packages/django/core/handlers/base.py", line 90, in get_response
    response = middleware_method(request)
  File "/usr/local/lib/python2.7/dist-packages/django/middleware/common.py", line 71, in process_request
    if (not urlresolvers.is_valid_path(request.path_info, urlconf) and
  File "/usr/local/lib/python2.7/dist-packages/django/core/urlresolvers.py", line 573, in is_valid_path
    resolve(path, urlconf)
  File "/usr/local/lib/python2.7/dist-packages/django/core/urlresolvers.py", line 453, in resolve
    return get_resolver(urlconf).resolve(path)
  File "/usr/local/lib/python2.7/dist-packages/django/core/urlresolvers.py", line 320, in resolve
    sub_match = pattern.resolve(new_path)
  File "/usr/local/lib/python2.7/dist-packages/django/core/urlresolvers.py", line 320, in resolve
    sub_match = pattern.resolve(new_path)
  File "/usr/local/lib/python2.7/dist-packages/django/core/urlresolvers.py", line 222, in resolve
    return ResolverMatch(self.callback, args, kwargs, self.name)
  File "/usr/local/lib/python2.7/dist-packages/django/core/urlresolvers.py", line 229, in callback
    self._callback = get_callable(self._callback_str)
  File "/usr/local/lib/python2.7/dist-packages/django/utils/functional.py", line 32, in wrapper
    result = func(*args)
  File "/usr/local/lib/python2.7/dist-packages/django/core/urlresolvers.py", line 100, in get_callable
    not module_has_submodule(import_module(parentmod), submod)):
  File "/usr/local/lib/python2.7/dist-packages/django/utils/importlib.py", line 40, in import_module
    __import__(name)
ImportError: No module named display
[2015-03-28 15:09:10,758] [django.request] [ERROR] Internal Server Error: /manage
Traceback (most recent call last):
  File "/usr/local/lib/python2.7/dist-packages/django/core/handlers/base.py", line 90, in get_response
    response = middleware_method(request)
  File "/usr/local/lib/python2.7/dist-packages/django/middleware/common.py", line 71, in process_request
    if (not urlresolvers.is_valid_path(request.path_info, urlconf) and
  File "/usr/local/lib/python2.7/dist-packages/django/core/urlresolvers.py", line 573, in is_valid_path
    resolve(path, urlconf)
  File "/usr/local/lib/python2.7/dist-packages/django/core/urlresolvers.py", line 453, in resolve
    return get_resolver(urlconf).resolve(path)
  File "/usr/local/lib/python2.7/dist-packages/django/core/urlresolvers.py", line 320, in resolve
    sub_match = pattern.resolve(new_path)
  File "/usr/local/lib/python2.7/dist-packages/django/core/urlresolvers.py", line 320, in resolve
    sub_match = pattern.resolve(new_path)
  File "/usr/local/lib/python2.7/dist-packages/django/core/urlresolvers.py", line 222, in resolve
    return ResolverMatch(self.callback, args, kwargs, self.name)
  File "/usr/local/lib/python2.7/dist-packages/django/core/urlresolvers.py", line 229, in callback
    self._callback = get_callable(self._callback_str)
  File "/usr/local/lib/python2.7/dist-packages/django/utils/functional.py", line 32, in wrapper
    result = func(*args)
  File "/usr/local/lib/python2.7/dist-packages/django/core/urlresolvers.py", line 96, in get_callable
    mod = import_module(mod_name)
  File "/usr/local/lib/python2.7/dist-packages/django/utils/importlib.py", line 40, in import_module
    __import__(name)
  File "/home/cheng-shiwen/Project/kuaiwen_server/application/display/views.py", line 8, in <module>
    from application.user.models import SecretUser, ForbidUser
ImportError: cannot import name ForbidUser
[2015-03-28 20:40:06,924] [django.request] [ERROR] Internal Server Error: /manage/user-stat
Traceback (most recent call last):
  File "/usr/local/lib/python2.7/dist-packages/django/core/handlers/base.py", line 114, in get_response
    response = wrapped_callback(request, *callback_args, **callback_kwargs)
  File "/home/cheng-shiwen/Project/kuaiwen_server/application/display/views.py", line 91, in user_stat
    return handle_response(result)
UnboundLocalError: local variable 'result' referenced before assignment
[2015-04-17 16:08:21,500] [django.request] [ERROR] Internal Server Error: /
Traceback (most recent call last):
  File "/usr/local/lib/python2.7/dist-packages/Django-1.7.7-py2.7.egg/django/core/handlers/base.py", line 98, in get_response
    resolver_match = resolver.resolve(request.path_info)
  File "/usr/local/lib/python2.7/dist-packages/Django-1.7.7-py2.7.egg/django/core/urlresolvers.py", line 343, in resolve
    for pattern in self.url_patterns:
  File "/usr/local/lib/python2.7/dist-packages/Django-1.7.7-py2.7.egg/django/core/urlresolvers.py", line 372, in url_patterns
    patterns = getattr(self.urlconf_module, "urlpatterns", self.urlconf_module)
  File "/usr/local/lib/python2.7/dist-packages/Django-1.7.7-py2.7.egg/django/core/urlresolvers.py", line 366, in urlconf_module
    self._urlconf_module = import_module(self.urlconf_name)
  File "/usr/lib/python2.7/importlib/__init__.py", line 37, in import_module
    __import__(name)
  File "/home/jing/python_app/tiaozy/tiaozy/urls.py", line 10, in <module>
    url(r'^', include('application.ssl_users.urls')),
  File "/usr/local/lib/python2.7/dist-packages/Django-1.7.7-py2.7.egg/django/conf/urls/__init__.py", line 28, in include
    urlconf_module = import_module(urlconf_module)
  File "/usr/lib/python2.7/importlib/__init__.py", line 37, in import_module
    __import__(name)
ImportError: No module named urls
[2015-04-17 16:08:22,515] [django.request] [ERROR] Internal Server Error: /favicon.ico
Traceback (most recent call last):
  File "/usr/local/lib/python2.7/dist-packages/Django-1.7.7-py2.7.egg/django/core/handlers/base.py", line 87, in get_response
    response = middleware_method(request)
  File "/usr/local/lib/python2.7/dist-packages/Django-1.7.7-py2.7.egg/django/middleware/common.py", line 72, in process_request
    if (not urlresolvers.is_valid_path(request.path_info, urlconf) and
  File "/usr/local/lib/python2.7/dist-packages/Django-1.7.7-py2.7.egg/django/core/urlresolvers.py", line 619, in is_valid_path
    resolve(path, urlconf)
  File "/usr/local/lib/python2.7/dist-packages/Django-1.7.7-py2.7.egg/django/core/urlresolvers.py", line 494, in resolve
    return get_resolver(urlconf).resolve(path)
  File "/usr/local/lib/python2.7/dist-packages/Django-1.7.7-py2.7.egg/django/core/urlresolvers.py", line 343, in resolve
    for pattern in self.url_patterns:
  File "/usr/local/lib/python2.7/dist-packages/Django-1.7.7-py2.7.egg/django/core/urlresolvers.py", line 372, in url_patterns
    patterns = getattr(self.urlconf_module, "urlpatterns", self.urlconf_module)
  File "/usr/local/lib/python2.7/dist-packages/Django-1.7.7-py2.7.egg/django/core/urlresolvers.py", line 366, in urlconf_module
    self._urlconf_module = import_module(self.urlconf_name)
  File "/usr/lib/python2.7/importlib/__init__.py", line 37, in import_module
    __import__(name)
  File "/home/jing/python_app/tiaozy/tiaozy/urls.py", line 10, in <module>
    url(r'^', include('application.ssl_users.urls')),
  File "/usr/local/lib/python2.7/dist-packages/Django-1.7.7-py2.7.egg/django/conf/urls/__init__.py", line 28, in include
    urlconf_module = import_module(urlconf_module)
  File "/usr/lib/python2.7/importlib/__init__.py", line 37, in import_module
    __import__(name)
ImportError: No module named urls
[2015-04-17 16:08:22,778] [django.request] [ERROR] Internal Server Error: /favicon.ico
Traceback (most recent call last):
  File "/usr/local/lib/python2.7/dist-packages/Django-1.7.7-py2.7.egg/django/core/handlers/base.py", line 87, in get_response
    response = middleware_method(request)
  File "/usr/local/lib/python2.7/dist-packages/Django-1.7.7-py2.7.egg/django/middleware/common.py", line 72, in process_request
    if (not urlresolvers.is_valid_path(request.path_info, urlconf) and
  File "/usr/local/lib/python2.7/dist-packages/Django-1.7.7-py2.7.egg/django/core/urlresolvers.py", line 619, in is_valid_path
    resolve(path, urlconf)
  File "/usr/local/lib/python2.7/dist-packages/Django-1.7.7-py2.7.egg/django/core/urlresolvers.py", line 494, in resolve
    return get_resolver(urlconf).resolve(path)
  File "/usr/local/lib/python2.7/dist-packages/Django-1.7.7-py2.7.egg/django/core/urlresolvers.py", line 343, in resolve
    for pattern in self.url_patterns:
  File "/usr/local/lib/python2.7/dist-packages/Django-1.7.7-py2.7.egg/django/core/urlresolvers.py", line 372, in url_patterns
    patterns = getattr(self.urlconf_module, "urlpatterns", self.urlconf_module)
  File "/usr/local/lib/python2.7/dist-packages/Django-1.7.7-py2.7.egg/django/core/urlresolvers.py", line 366, in urlconf_module
    self._urlconf_module = import_module(self.urlconf_name)
  File "/usr/lib/python2.7/importlib/__init__.py", line 37, in import_module
    __import__(name)
  File "/home/jing/python_app/tiaozy/tiaozy/urls.py", line 10, in <module>
    url(r'^', include('application.ssl_users.urls')),
  File "/usr/local/lib/python2.7/dist-packages/Django-1.7.7-py2.7.egg/django/conf/urls/__init__.py", line 28, in include
    urlconf_module = import_module(urlconf_module)
  File "/usr/lib/python2.7/importlib/__init__.py", line 37, in import_module
    __import__(name)
ImportError: No module named urls
[2015-04-17 16:24:21,632] [django.request] [ERROR] Internal Server Error: /
Traceback (most recent call last):
  File "/usr/local/lib/python2.7/dist-packages/Django-1.7.7-py2.7.egg/django/core/handlers/base.py", line 111, in get_response
    response = wrapped_callback(request, *callback_args, **callback_kwargs)
  File "/home/jing/python_app/tiaozy/application/html_files/views.py", line 5, in index
    return render_to_response('index.html')
NameError: global name 'render_to_response' is not defined
