[2015-04-22 08:12:11,546] [django.request] [ERROR] Internal Server Error: /get-user-all-posts
Traceback (most recent call last):
  File "/usr/local/lib/python2.7/dist-packages/django/core/handlers/base.py", line 204, in get_response
    response = middleware_method(request, response)
  File "/usr/local/lib/python2.7/dist-packages/django/middleware/clickjacking.py", line 31, in process_response
    if response.get('X-Frame-Options', None) is not None:
AttributeError: 'list' object has no attribute 'get'
[2015-04-22 08:13:05,609] [django.request] [ERROR] Internal Server Error: /get-user-all-posts
Traceback (most recent call last):
  File "/usr/local/lib/python2.7/dist-packages/django/core/handlers/base.py", line 204, in get_response
    response = middleware_method(request, response)
  File "/usr/local/lib/python2.7/dist-packages/django/middleware/clickjacking.py", line 31, in process_response
    if response.get('X-Frame-Options', None) is not None:
AttributeError: 'list' object has no attribute 'get'
[2015-04-22 08:14:11,529] [django.request] [ERROR] Internal Server Error: /get-user-all-posts
Traceback (most recent call last):
  File "/usr/local/lib/python2.7/dist-packages/django/core/handlers/base.py", line 204, in get_response
    response = middleware_method(request, response)
  File "/usr/local/lib/python2.7/dist-packages/django/middleware/clickjacking.py", line 31, in process_response
    if response.get('X-Frame-Options', None) is not None:
AttributeError: 'list' object has no attribute 'get'
[2015-04-22 08:15:47,245] [django.request] [ERROR] Internal Server Error: /get-user-all-posts
Traceback (most recent call last):
  File "/usr/local/lib/python2.7/dist-packages/django/core/handlers/base.py", line 204, in get_response
    response = middleware_method(request, response)
  File "/usr/local/lib/python2.7/dist-packages/django/middleware/clickjacking.py", line 31, in process_response
    if response.get('X-Frame-Options', None) is not None:
AttributeError: 'list' object has no attribute 'get'
[2015-04-22 08:16:23,178] [django.request] [ERROR] Internal Server Error: /get-user-all-posts
Traceback (most recent call last):
  File "/usr/local/lib/python2.7/dist-packages/django/core/handlers/base.py", line 204, in get_response
    response = middleware_method(request, response)
  File "/usr/local/lib/python2.7/dist-packages/django/middleware/clickjacking.py", line 31, in process_response
    if response.get('X-Frame-Options', None) is not None:
AttributeError: 'list' object has no attribute 'get'
[2015-04-22 08:19:27,341] [django.request] [ERROR] Internal Server Error: /get-user-all-posts
Traceback (most recent call last):
  File "/usr/local/lib/python2.7/dist-packages/django/core/handlers/base.py", line 204, in get_response
    response = middleware_method(request, response)
  File "/usr/local/lib/python2.7/dist-packages/django/middleware/clickjacking.py", line 31, in process_response
    if response.get('X-Frame-Options', None) is not None:
AttributeError: 'list' object has no attribute 'get'
[2015-04-22 08:21:35,635] [django.request] [ERROR] Internal Server Error: /get-user-all-posts
Traceback (most recent call last):
  File "/usr/local/lib/python2.7/dist-packages/django/core/handlers/base.py", line 204, in get_response
    response = middleware_method(request, response)
  File "/usr/local/lib/python2.7/dist-packages/django/middleware/clickjacking.py", line 31, in process_response
    if response.get('X-Frame-Options', None) is not None:
AttributeError: 'list' object has no attribute 'get'
[2015-04-22 08:22:55,811] [django.request] [ERROR] Internal Server Error: /get-user-all-posts
Traceback (most recent call last):
  File "/usr/local/lib/python2.7/dist-packages/django/core/handlers/base.py", line 111, in get_response
    response = wrapped_callback(request, *callback_args, **callback_kwargs)
  File "/home/jing/python_server/tiaozy/application/display_items/views.py", line 312, in getAllPostsForUser
    print postUser
  File "/home/jing/python_server/tiaozy/application/ssl_users/models.py", line 15, in __str__
    return "username:%s\tphone:%s\temail:%s\t"%(self.username,self.mobilephone,self.email)
AttributeError: 'tzy_users' object has no attribute 'mobilephone'
[2015-04-22 08:23:22,508] [django.request] [ERROR] Internal Server Error: /get-user-all-posts
Traceback (most recent call last):
  File "/usr/local/lib/python2.7/dist-packages/django/core/handlers/base.py", line 111, in get_response
    response = wrapped_callback(request, *callback_args, **callback_kwargs)
  File "/home/jing/python_server/tiaozy/application/display_items/views.py", line 312, in getAllPostsForUser
    print postUser
  File "/home/jing/python_server/tiaozy/application/ssl_users/models.py", line 15, in __str__
    return "username:%s\tphone:%s\temail:%s\t"%(self.username,self.mobilephone,self.email)
AttributeError: 'tzy_users' object has no attribute 'mobilephone'
[2015-04-22 08:23:48,671] [django.request] [ERROR] Internal Server Error: /get-user-all-posts
Traceback (most recent call last):
  File "/usr/local/lib/python2.7/dist-packages/django/core/handlers/base.py", line 111, in get_response
    response = wrapped_callback(request, *callback_args, **callback_kwargs)
  File "/home/jing/python_server/tiaozy/application/display_items/views.py", line 312, in getAllPostsForUser
    print postUser
  File "/home/jing/python_server/tiaozy/application/ssl_users/models.py", line 15, in __str__
    return "username:%s\tphone:%s\temail:%s\t"%(self.username,self.mobilephone,self.email)
AttributeError: 'tzy_users' object has no attribute 'mobilephone'
[2015-04-22 08:26:49,192] [django.request] [ERROR] Internal Server Error: /get-user-all-posts
Traceback (most recent call last):
  File "/usr/local/lib/python2.7/dist-packages/django/core/handlers/base.py", line 204, in get_response
    response = middleware_method(request, response)
  File "/usr/local/lib/python2.7/dist-packages/django/middleware/clickjacking.py", line 31, in process_response
    if response.get('X-Frame-Options', None) is not None:
AttributeError: 'list' object has no attribute 'get'
[2015-04-22 08:27:15,441] [django.request] [ERROR] Internal Server Error: /get-user-all-posts
Traceback (most recent call last):
  File "/usr/local/lib/python2.7/dist-packages/django/core/handlers/base.py", line 204, in get_response
    response = middleware_method(request, response)
  File "/usr/local/lib/python2.7/dist-packages/django/middleware/clickjacking.py", line 31, in process_response
    if response.get('X-Frame-Options', None) is not None:
AttributeError: 'list' object has no attribute 'get'
[2015-04-22 08:28:43,096] [django.request] [ERROR] Internal Server Error: /get-user-all-posts
Traceback (most recent call last):
  File "/usr/local/lib/python2.7/dist-packages/django/core/handlers/base.py", line 204, in get_response
    response = middleware_method(request, response)
  File "/usr/local/lib/python2.7/dist-packages/django/middleware/clickjacking.py", line 31, in process_response
    if response.get('X-Frame-Options', None) is not None:
AttributeError: 'list' object has no attribute 'get'
[2015-04-22 08:31:03,213] [django.request] [ERROR] Internal Server Error: /get-user-all-posts
Traceback (most recent call last):
  File "/usr/local/lib/python2.7/dist-packages/django/core/handlers/base.py", line 204, in get_response
    response = middleware_method(request, response)
  File "/usr/local/lib/python2.7/dist-packages/django/middleware/clickjacking.py", line 31, in process_response
    if response.get('X-Frame-Options', None) is not None:
AttributeError: 'list' object has no attribute 'get'
[2015-04-22 08:34:43,058] [django.request] [ERROR] Internal Server Error: /get-user-all-posts
Traceback (most recent call last):
  File "/usr/local/lib/python2.7/dist-packages/django/core/handlers/base.py", line 204, in get_response
    response = middleware_method(request, response)
  File "/usr/local/lib/python2.7/dist-packages/django/middleware/clickjacking.py", line 31, in process_response
    if response.get('X-Frame-Options', None) is not None:
AttributeError: 'list' object has no attribute 'get'
[2015-04-22 08:35:39,091] [django.request] [ERROR] Internal Server Error: /get-user-all-posts
Traceback (most recent call last):
  File "/usr/local/lib/python2.7/dist-packages/django/core/handlers/base.py", line 87, in get_response
    response = middleware_method(request)
  File "/usr/local/lib/python2.7/dist-packages/django/middleware/common.py", line 72, in process_request
    if (not urlresolvers.is_valid_path(request.path_info, urlconf) and
  File "/usr/local/lib/python2.7/dist-packages/django/core/urlresolvers.py", line 619, in is_valid_path
    resolve(path, urlconf)
  File "/usr/local/lib/python2.7/dist-packages/django/core/urlresolvers.py", line 494, in resolve
    return get_resolver(urlconf).resolve(path)
  File "/usr/local/lib/python2.7/dist-packages/django/core/urlresolvers.py", line 345, in resolve
    sub_match = pattern.resolve(new_path)
  File "/usr/local/lib/python2.7/dist-packages/django/core/urlresolvers.py", line 345, in resolve
    sub_match = pattern.resolve(new_path)
  File "/usr/local/lib/python2.7/dist-packages/django/core/urlresolvers.py", line 224, in resolve
    return ResolverMatch(self.callback, args, kwargs, self.name)
  File "/usr/local/lib/python2.7/dist-packages/django/core/urlresolvers.py", line 231, in callback
    self._callback = get_callable(self._callback_str)
  File "/usr/local/lib/python2.7/dist-packages/django/utils/lru_cache.py", line 101, in wrapper
    result = user_function(*args, **kwds)
  File "/usr/local/lib/python2.7/dist-packages/django/core/urlresolvers.py", line 118, in get_callable
    (lookup_view, mod_name))
ViewDoesNotExist: Could not import application.display_items.views.getAllPostsForUser. View does not exist in module application.display_items.views.
[2015-04-22 08:36:24,269] [django.request] [ERROR] Internal Server Error: /get-user-all-posts
Traceback (most recent call last):
  File "/usr/local/lib/python2.7/dist-packages/django/core/handlers/base.py", line 87, in get_response
    response = middleware_method(request)
  File "/usr/local/lib/python2.7/dist-packages/django/middleware/common.py", line 72, in process_request
    if (not urlresolvers.is_valid_path(request.path_info, urlconf) and
  File "/usr/local/lib/python2.7/dist-packages/django/core/urlresolvers.py", line 619, in is_valid_path
    resolve(path, urlconf)
  File "/usr/local/lib/python2.7/dist-packages/django/core/urlresolvers.py", line 494, in resolve
    return get_resolver(urlconf).resolve(path)
  File "/usr/local/lib/python2.7/dist-packages/django/core/urlresolvers.py", line 345, in resolve
    sub_match = pattern.resolve(new_path)
  File "/usr/local/lib/python2.7/dist-packages/django/core/urlresolvers.py", line 345, in resolve
    sub_match = pattern.resolve(new_path)
  File "/usr/local/lib/python2.7/dist-packages/django/core/urlresolvers.py", line 224, in resolve
    return ResolverMatch(self.callback, args, kwargs, self.name)
  File "/usr/local/lib/python2.7/dist-packages/django/core/urlresolvers.py", line 231, in callback
    self._callback = get_callable(self._callback_str)
  File "/usr/local/lib/python2.7/dist-packages/django/utils/lru_cache.py", line 101, in wrapper
    result = user_function(*args, **kwds)
  File "/usr/local/lib/python2.7/dist-packages/django/core/urlresolvers.py", line 118, in get_callable
    (lookup_view, mod_name))
ViewDoesNotExist: Could not import application.display_items.views.getAllPostsForUser. View does not exist in module application.display_items.views.
[2015-04-22 08:38:01,596] [django.request] [ERROR] Internal Server Error: /get-user-all-posts
Traceback (most recent call last):
  File "/usr/local/lib/python2.7/dist-packages/django/core/handlers/base.py", line 87, in get_response
    response = middleware_method(request)
  File "/usr/local/lib/python2.7/dist-packages/django/middleware/common.py", line 72, in process_request
    if (not urlresolvers.is_valid_path(request.path_info, urlconf) and
  File "/usr/local/lib/python2.7/dist-packages/django/core/urlresolvers.py", line 619, in is_valid_path
    resolve(path, urlconf)
  File "/usr/local/lib/python2.7/dist-packages/django/core/urlresolvers.py", line 494, in resolve
    return get_resolver(urlconf).resolve(path)
  File "/usr/local/lib/python2.7/dist-packages/django/core/urlresolvers.py", line 345, in resolve
    sub_match = pattern.resolve(new_path)
  File "/usr/local/lib/python2.7/dist-packages/django/core/urlresolvers.py", line 345, in resolve
    sub_match = pattern.resolve(new_path)
  File "/usr/local/lib/python2.7/dist-packages/django/core/urlresolvers.py", line 224, in resolve
    return ResolverMatch(self.callback, args, kwargs, self.name)
  File "/usr/local/lib/python2.7/dist-packages/django/core/urlresolvers.py", line 231, in callback
    self._callback = get_callable(self._callback_str)
  File "/usr/local/lib/python2.7/dist-packages/django/utils/lru_cache.py", line 101, in wrapper
    result = user_function(*args, **kwds)
  File "/usr/local/lib/python2.7/dist-packages/django/core/urlresolvers.py", line 118, in get_callable
    (lookup_view, mod_name))
ViewDoesNotExist: Could not import application.display_items.views.getAllPostsForUser. View does not exist in module application.display_items.views.
[2015-04-22 14:41:01,121] [django.request] [ERROR] Internal Server Error: /get-on-selling
Traceback (most recent call last):
  File "/usr/local/lib/python2.7/dist-packages/Django-1.7.7-py2.7.egg/django/core/handlers/base.py", line 87, in get_response
    response = middleware_method(request)
  File "/usr/local/lib/python2.7/dist-packages/Django-1.7.7-py2.7.egg/django/middleware/common.py", line 72, in process_request
    if (not urlresolvers.is_valid_path(request.path_info, urlconf) and
  File "/usr/local/lib/python2.7/dist-packages/Django-1.7.7-py2.7.egg/django/core/urlresolvers.py", line 619, in is_valid_path
    resolve(path, urlconf)
  File "/usr/local/lib/python2.7/dist-packages/Django-1.7.7-py2.7.egg/django/core/urlresolvers.py", line 494, in resolve
    return get_resolver(urlconf).resolve(path)
  File "/usr/local/lib/python2.7/dist-packages/Django-1.7.7-py2.7.egg/django/core/urlresolvers.py", line 345, in resolve
    sub_match = pattern.resolve(new_path)
  File "/usr/local/lib/python2.7/dist-packages/Django-1.7.7-py2.7.egg/django/core/urlresolvers.py", line 345, in resolve
    sub_match = pattern.resolve(new_path)
  File "/usr/local/lib/python2.7/dist-packages/Django-1.7.7-py2.7.egg/django/core/urlresolvers.py", line 224, in resolve
    return ResolverMatch(self.callback, args, kwargs, self.name)
  File "/usr/local/lib/python2.7/dist-packages/Django-1.7.7-py2.7.egg/django/core/urlresolvers.py", line 231, in callback
    self._callback = get_callable(self._callback_str)
  File "/usr/local/lib/python2.7/dist-packages/Django-1.7.7-py2.7.egg/django/utils/lru_cache.py", line 101, in wrapper
    result = user_function(*args, **kwds)
  File "/usr/local/lib/python2.7/dist-packages/Django-1.7.7-py2.7.egg/django/core/urlresolvers.py", line 97, in get_callable
    mod = import_module(mod_name)
  File "/usr/lib/python2.7/importlib/__init__.py", line 37, in import_module
    __import__(name)
  File "/home/jing/python_app/tiaozy/application/display_items/views.py", line 13
    from application.display_items.models import
                                               ^
SyntaxError: invalid syntax
[2015-04-22 14:41:01,148] [django.request] [ERROR] Internal Server Error: /get-on-asking
Traceback (most recent call last):
  File "/usr/local/lib/python2.7/dist-packages/Django-1.7.7-py2.7.egg/django/core/handlers/base.py", line 87, in get_response
    response = middleware_method(request)
  File "/usr/local/lib/python2.7/dist-packages/Django-1.7.7-py2.7.egg/django/middleware/common.py", line 72, in process_request
    if (not urlresolvers.is_valid_path(request.path_info, urlconf) and
  File "/usr/local/lib/python2.7/dist-packages/Django-1.7.7-py2.7.egg/django/core/urlresolvers.py", line 619, in is_valid_path
    resolve(path, urlconf)
  File "/usr/local/lib/python2.7/dist-packages/Django-1.7.7-py2.7.egg/django/core/urlresolvers.py", line 494, in resolve
    return get_resolver(urlconf).resolve(path)
  File "/usr/local/lib/python2.7/dist-packages/Django-1.7.7-py2.7.egg/django/core/urlresolvers.py", line 345, in resolve
    sub_match = pattern.resolve(new_path)
  File "/usr/local/lib/python2.7/dist-packages/Django-1.7.7-py2.7.egg/django/core/urlresolvers.py", line 345, in resolve
    sub_match = pattern.resolve(new_path)
  File "/usr/local/lib/python2.7/dist-packages/Django-1.7.7-py2.7.egg/django/core/urlresolvers.py", line 224, in resolve
    return ResolverMatch(self.callback, args, kwargs, self.name)
  File "/usr/local/lib/python2.7/dist-packages/Django-1.7.7-py2.7.egg/django/core/urlresolvers.py", line 231, in callback
    self._callback = get_callable(self._callback_str)
  File "/usr/local/lib/python2.7/dist-packages/Django-1.7.7-py2.7.egg/django/utils/lru_cache.py", line 101, in wrapper
    result = user_function(*args, **kwds)
  File "/usr/local/lib/python2.7/dist-packages/Django-1.7.7-py2.7.egg/django/core/urlresolvers.py", line 97, in get_callable
    mod = import_module(mod_name)
  File "/usr/lib/python2.7/importlib/__init__.py", line 37, in import_module
    __import__(name)
  File "/home/jing/python_app/tiaozy/application/display_items/views.py", line 13
    from application.display_items.models import
                                               ^
SyntaxError: invalid syntax
[2015-04-22 14:42:46,125] [django.request] [ERROR] Internal Server Error: /get-on-selling
Traceback (most recent call last):
  File "/usr/local/lib/python2.7/dist-packages/Django-1.7.7-py2.7.egg/django/core/handlers/base.py", line 87, in get_response
    response = middleware_method(request)
  File "/usr/local/lib/python2.7/dist-packages/Django-1.7.7-py2.7.egg/django/middleware/common.py", line 72, in process_request
    if (not urlresolvers.is_valid_path(request.path_info, urlconf) and
  File "/usr/local/lib/python2.7/dist-packages/Django-1.7.7-py2.7.egg/django/core/urlresolvers.py", line 619, in is_valid_path
    resolve(path, urlconf)
  File "/usr/local/lib/python2.7/dist-packages/Django-1.7.7-py2.7.egg/django/core/urlresolvers.py", line 494, in resolve
    return get_resolver(urlconf).resolve(path)
  File "/usr/local/lib/python2.7/dist-packages/Django-1.7.7-py2.7.egg/django/core/urlresolvers.py", line 345, in resolve
    sub_match = pattern.resolve(new_path)
  File "/usr/local/lib/python2.7/dist-packages/Django-1.7.7-py2.7.egg/django/core/urlresolvers.py", line 345, in resolve
    sub_match = pattern.resolve(new_path)
  File "/usr/local/lib/python2.7/dist-packages/Django-1.7.7-py2.7.egg/django/core/urlresolvers.py", line 224, in resolve
    return ResolverMatch(self.callback, args, kwargs, self.name)
  File "/usr/local/lib/python2.7/dist-packages/Django-1.7.7-py2.7.egg/django/core/urlresolvers.py", line 231, in callback
    self._callback = get_callable(self._callback_str)
  File "/usr/local/lib/python2.7/dist-packages/Django-1.7.7-py2.7.egg/django/utils/lru_cache.py", line 101, in wrapper
    result = user_function(*args, **kwds)
  File "/usr/local/lib/python2.7/dist-packages/Django-1.7.7-py2.7.egg/django/core/urlresolvers.py", line 97, in get_callable
    mod = import_module(mod_name)
  File "/usr/lib/python2.7/importlib/__init__.py", line 37, in import_module
    __import__(name)
  File "/home/jing/python_app/tiaozy/application/display_items/views.py", line 295
    result["MessageCount"] = len(item_messages_table.objects.filter(Item=))
                                                                         ^
SyntaxError: invalid syntax
[2015-04-22 14:42:46,151] [django.request] [ERROR] Internal Server Error: /get-on-asking
Traceback (most recent call last):
  File "/usr/local/lib/python2.7/dist-packages/Django-1.7.7-py2.7.egg/django/core/handlers/base.py", line 87, in get_response
    response = middleware_method(request)
  File "/usr/local/lib/python2.7/dist-packages/Django-1.7.7-py2.7.egg/django/middleware/common.py", line 72, in process_request
    if (not urlresolvers.is_valid_path(request.path_info, urlconf) and
  File "/usr/local/lib/python2.7/dist-packages/Django-1.7.7-py2.7.egg/django/core/urlresolvers.py", line 619, in is_valid_path
    resolve(path, urlconf)
  File "/usr/local/lib/python2.7/dist-packages/Django-1.7.7-py2.7.egg/django/core/urlresolvers.py", line 494, in resolve
    return get_resolver(urlconf).resolve(path)
  File "/usr/local/lib/python2.7/dist-packages/Django-1.7.7-py2.7.egg/django/core/urlresolvers.py", line 345, in resolve
    sub_match = pattern.resolve(new_path)
  File "/usr/local/lib/python2.7/dist-packages/Django-1.7.7-py2.7.egg/django/core/urlresolvers.py", line 345, in resolve
    sub_match = pattern.resolve(new_path)
  File "/usr/local/lib/python2.7/dist-packages/Django-1.7.7-py2.7.egg/django/core/urlresolvers.py", line 224, in resolve
    return ResolverMatch(self.callback, args, kwargs, self.name)
  File "/usr/local/lib/python2.7/dist-packages/Django-1.7.7-py2.7.egg/django/core/urlresolvers.py", line 231, in callback
    self._callback = get_callable(self._callback_str)
  File "/usr/local/lib/python2.7/dist-packages/Django-1.7.7-py2.7.egg/django/utils/lru_cache.py", line 101, in wrapper
    result = user_function(*args, **kwds)
  File "/usr/local/lib/python2.7/dist-packages/Django-1.7.7-py2.7.egg/django/core/urlresolvers.py", line 97, in get_callable
    mod = import_module(mod_name)
  File "/usr/lib/python2.7/importlib/__init__.py", line 37, in import_module
    __import__(name)
  File "/home/jing/python_app/tiaozy/application/display_items/views.py", line 295
    result["MessageCount"] = len(item_messages_table.objects.filter(Item=))
                                                                         ^
SyntaxError: invalid syntax
[2015-04-22 14:43:01,116] [django.request] [ERROR] Internal Server Error: /get-on-selling
Traceback (most recent call last):
  File "/usr/local/lib/python2.7/dist-packages/Django-1.7.7-py2.7.egg/django/core/handlers/base.py", line 87, in get_response
    response = middleware_method(request)
  File "/usr/local/lib/python2.7/dist-packages/Django-1.7.7-py2.7.egg/django/middleware/common.py", line 72, in process_request
    if (not urlresolvers.is_valid_path(request.path_info, urlconf) and
  File "/usr/local/lib/python2.7/dist-packages/Django-1.7.7-py2.7.egg/django/core/urlresolvers.py", line 619, in is_valid_path
    resolve(path, urlconf)
  File "/usr/local/lib/python2.7/dist-packages/Django-1.7.7-py2.7.egg/django/core/urlresolvers.py", line 494, in resolve
    return get_resolver(urlconf).resolve(path)
  File "/usr/local/lib/python2.7/dist-packages/Django-1.7.7-py2.7.egg/django/core/urlresolvers.py", line 345, in resolve
    sub_match = pattern.resolve(new_path)
  File "/usr/local/lib/python2.7/dist-packages/Django-1.7.7-py2.7.egg/django/core/urlresolvers.py", line 345, in resolve
    sub_match = pattern.resolve(new_path)
  File "/usr/local/lib/python2.7/dist-packages/Django-1.7.7-py2.7.egg/django/core/urlresolvers.py", line 224, in resolve
    return ResolverMatch(self.callback, args, kwargs, self.name)
  File "/usr/local/lib/python2.7/dist-packages/Django-1.7.7-py2.7.egg/django/core/urlresolvers.py", line 231, in callback
    self._callback = get_callable(self._callback_str)
  File "/usr/local/lib/python2.7/dist-packages/Django-1.7.7-py2.7.egg/django/utils/lru_cache.py", line 101, in wrapper
    result = user_function(*args, **kwds)
  File "/usr/local/lib/python2.7/dist-packages/Django-1.7.7-py2.7.egg/django/core/urlresolvers.py", line 97, in get_callable
    mod = import_module(mod_name)
  File "/usr/lib/python2.7/importlib/__init__.py", line 37, in import_module
    __import__(name)
  File "/home/jing/python_app/tiaozy/application/display_items/views.py", line 295
    result["MessageCount"] = len(item_messages_table.objects.filter(Item=))
                                                                         ^
SyntaxError: invalid syntax
[2015-04-22 14:43:01,151] [django.request] [ERROR] Internal Server Error: /get-on-asking
Traceback (most recent call last):
  File "/usr/local/lib/python2.7/dist-packages/Django-1.7.7-py2.7.egg/django/core/handlers/base.py", line 87, in get_response
    response = middleware_method(request)
  File "/usr/local/lib/python2.7/dist-packages/Django-1.7.7-py2.7.egg/django/middleware/common.py", line 72, in process_request
    if (not urlresolvers.is_valid_path(request.path_info, urlconf) and
  File "/usr/local/lib/python2.7/dist-packages/Django-1.7.7-py2.7.egg/django/core/urlresolvers.py", line 619, in is_valid_path
    resolve(path, urlconf)
  File "/usr/local/lib/python2.7/dist-packages/Django-1.7.7-py2.7.egg/django/core/urlresolvers.py", line 494, in resolve
    return get_resolver(urlconf).resolve(path)
  File "/usr/local/lib/python2.7/dist-packages/Django-1.7.7-py2.7.egg/django/core/urlresolvers.py", line 345, in resolve
    sub_match = pattern.resolve(new_path)
  File "/usr/local/lib/python2.7/dist-packages/Django-1.7.7-py2.7.egg/django/core/urlresolvers.py", line 345, in resolve
    sub_match = pattern.resolve(new_path)
  File "/usr/local/lib/python2.7/dist-packages/Django-1.7.7-py2.7.egg/django/core/urlresolvers.py", line 224, in resolve
    return ResolverMatch(self.callback, args, kwargs, self.name)
  File "/usr/local/lib/python2.7/dist-packages/Django-1.7.7-py2.7.egg/django/core/urlresolvers.py", line 231, in callback
    self._callback = get_callable(self._callback_str)
  File "/usr/local/lib/python2.7/dist-packages/Django-1.7.7-py2.7.egg/django/utils/lru_cache.py", line 101, in wrapper
    result = user_function(*args, **kwds)
  File "/usr/local/lib/python2.7/dist-packages/Django-1.7.7-py2.7.egg/django/core/urlresolvers.py", line 97, in get_callable
    mod = import_module(mod_name)
  File "/usr/lib/python2.7/importlib/__init__.py", line 37, in import_module
    __import__(name)
  File "/home/jing/python_app/tiaozy/application/display_items/views.py", line 295
    result["MessageCount"] = len(item_messages_table.objects.filter(Item=))
                                                                         ^
SyntaxError: invalid syntax
[2015-04-23 03:00:10,117] [django.request] [ERROR] Internal Server Error: /open_item
Traceback (most recent call last):
  File "/usr/local/lib/python2.7/dist-packages/django/core/handlers/base.py", line 87, in get_response
    response = middleware_method(request)
  File "/usr/local/lib/python2.7/dist-packages/django/middleware/common.py", line 72, in process_request
    if (not urlresolvers.is_valid_path(request.path_info, urlconf) and
  File "/usr/local/lib/python2.7/dist-packages/django/core/urlresolvers.py", line 619, in is_valid_path
    resolve(path, urlconf)
  File "/usr/local/lib/python2.7/dist-packages/django/core/urlresolvers.py", line 494, in resolve
    return get_resolver(urlconf).resolve(path)
  File "/usr/local/lib/python2.7/dist-packages/django/core/urlresolvers.py", line 345, in resolve
    sub_match = pattern.resolve(new_path)
  File "/usr/local/lib/python2.7/dist-packages/django/core/urlresolvers.py", line 345, in resolve
    sub_match = pattern.resolve(new_path)
  File "/usr/local/lib/python2.7/dist-packages/django/core/urlresolvers.py", line 224, in resolve
    return ResolverMatch(self.callback, args, kwargs, self.name)
  File "/usr/local/lib/python2.7/dist-packages/django/core/urlresolvers.py", line 231, in callback
    self._callback = get_callable(self._callback_str)
  File "/usr/local/lib/python2.7/dist-packages/django/utils/lru_cache.py", line 101, in wrapper
    result = user_function(*args, **kwds)
  File "/usr/local/lib/python2.7/dist-packages/django/core/urlresolvers.py", line 97, in get_callable
    mod = import_module(mod_name)
  File "/usr/lib/python2.7/importlib/__init__.py", line 37, in import_module
    __import__(name)
  File "/home/jing/python_server/tiaozy/application/display_items/views.py", line 384
    result["PostTime"] = formatTime(message.PostTime,"%Y-%m-%d %H:%M")
                       ^
SyntaxError: invalid syntax
[2015-04-23 03:15:14,935] [django.request] [ERROR] Internal Server Error: /open_item
Traceback (most recent call last):
  File "/usr/local/lib/python2.7/dist-packages/django/core/handlers/base.py", line 87, in get_response
    response = middleware_method(request)
  File "/usr/local/lib/python2.7/dist-packages/django/middleware/common.py", line 72, in process_request
    if (not urlresolvers.is_valid_path(request.path_info, urlconf) and
  File "/usr/local/lib/python2.7/dist-packages/django/core/urlresolvers.py", line 619, in is_valid_path
    resolve(path, urlconf)
  File "/usr/local/lib/python2.7/dist-packages/django/core/urlresolvers.py", line 494, in resolve
    return get_resolver(urlconf).resolve(path)
  File "/usr/local/lib/python2.7/dist-packages/django/core/urlresolvers.py", line 345, in resolve
    sub_match = pattern.resolve(new_path)
  File "/usr/local/lib/python2.7/dist-packages/django/core/urlresolvers.py", line 345, in resolve
    sub_match = pattern.resolve(new_path)
  File "/usr/local/lib/python2.7/dist-packages/django/core/urlresolvers.py", line 224, in resolve
    return ResolverMatch(self.callback, args, kwargs, self.name)
  File "/usr/local/lib/python2.7/dist-packages/django/core/urlresolvers.py", line 231, in callback
    self._callback = get_callable(self._callback_str)
  File "/usr/local/lib/python2.7/dist-packages/django/utils/lru_cache.py", line 101, in wrapper
    result = user_function(*args, **kwds)
  File "/usr/local/lib/python2.7/dist-packages/django/core/urlresolvers.py", line 97, in get_callable
    mod = import_module(mod_name)
  File "/usr/lib/python2.7/importlib/__init__.py", line 37, in import_module
    __import__(name)
  File "/home/jing/python_server/tiaozy/application/display_items/views.py", line 355
    message_str = request.user.username+" : "+message
    ^
IndentationError: unexpected indent
[2015-04-23 16:57:14,658] [django.request] [ERROR] Internal Server Error: /get-ssl-eecp-books
Traceback (most recent call last):
  File "/usr/local/lib/python2.7/dist-packages/Django-1.7.7-py2.7.egg/django/core/handlers/base.py", line 87, in get_response
    response = middleware_method(request)
  File "/usr/local/lib/python2.7/dist-packages/Django-1.7.7-py2.7.egg/django/middleware/common.py", line 72, in process_request
    if (not urlresolvers.is_valid_path(request.path_info, urlconf) and
  File "/usr/local/lib/python2.7/dist-packages/Django-1.7.7-py2.7.egg/django/core/urlresolvers.py", line 619, in is_valid_path
    resolve(path, urlconf)
  File "/usr/local/lib/python2.7/dist-packages/Django-1.7.7-py2.7.egg/django/core/urlresolvers.py", line 494, in resolve
    return get_resolver(urlconf).resolve(path)
  File "/usr/local/lib/python2.7/dist-packages/Django-1.7.7-py2.7.egg/django/core/urlresolvers.py", line 345, in resolve
    sub_match = pattern.resolve(new_path)
  File "/usr/local/lib/python2.7/dist-packages/Django-1.7.7-py2.7.egg/django/core/urlresolvers.py", line 345, in resolve
    sub_match = pattern.resolve(new_path)
  File "/usr/local/lib/python2.7/dist-packages/Django-1.7.7-py2.7.egg/django/core/urlresolvers.py", line 224, in resolve
    return ResolverMatch(self.callback, args, kwargs, self.name)
  File "/usr/local/lib/python2.7/dist-packages/Django-1.7.7-py2.7.egg/django/core/urlresolvers.py", line 231, in callback
    self._callback = get_callable(self._callback_str)
  File "/usr/local/lib/python2.7/dist-packages/Django-1.7.7-py2.7.egg/django/utils/lru_cache.py", line 101, in wrapper
    result = user_function(*args, **kwds)
  File "/usr/local/lib/python2.7/dist-packages/Django-1.7.7-py2.7.egg/django/core/urlresolvers.py", line 118, in get_callable
    (lookup_view, mod_name))
ViewDoesNotExist: Could not import application.display_items.views.getSSLEecpnBooks. View does not exist in module application.display_items.views.
[2015-04-24 08:24:32,169] [django.request] [ERROR] Internal Server Error: /reg/
Traceback (most recent call last):
  File "/usr/local/lib/python2.7/dist-packages/django/core/handlers/base.py", line 98, in get_response
    resolver_match = resolver.resolve(request.path_info)
  File "/usr/local/lib/python2.7/dist-packages/django/core/urlresolvers.py", line 345, in resolve
    sub_match = pattern.resolve(new_path)
  File "/usr/local/lib/python2.7/dist-packages/django/core/urlresolvers.py", line 345, in resolve
    sub_match = pattern.resolve(new_path)
  File "/usr/local/lib/python2.7/dist-packages/django/core/urlresolvers.py", line 224, in resolve
    return ResolverMatch(self.callback, args, kwargs, self.name)
  File "/usr/local/lib/python2.7/dist-packages/django/core/urlresolvers.py", line 231, in callback
    self._callback = get_callable(self._callback_str)
  File "/usr/local/lib/python2.7/dist-packages/django/utils/lru_cache.py", line 101, in wrapper
    result = user_function(*args, **kwds)
  File "/usr/local/lib/python2.7/dist-packages/django/core/urlresolvers.py", line 97, in get_callable
    mod = import_module(mod_name)
  File "/usr/lib/python2.7/importlib/__init__.py", line 37, in import_module
    __import__(name)
  File "/home/jing/python_server/tiaozy/application/ssl_users/views.py", line 102
    if request.POST.get('qq')
                            ^
SyntaxError: invalid syntax
[2015-04-24 10:24:16,381] [django.request] [ERROR] Internal Server Error: /get-my-personal-info
Traceback (most recent call last):
  File "/usr/local/lib/python2.7/dist-packages/django/core/handlers/base.py", line 111, in get_response
    response = wrapped_callback(request, *callback_args, **callback_kwargs)
  File "/home/jing/python_server/tiaozy/application/ssl_users/views.py", line 198, in getMyPersonalInfo
    return handle_response(result)
NameError: global name 'handle_response' is not defined
[2015-04-24 10:24:17,032] [django.request] [ERROR] Internal Server Error: /get-my-personal-info
Traceback (most recent call last):
  File "/usr/local/lib/python2.7/dist-packages/django/core/handlers/base.py", line 111, in get_response
    response = wrapped_callback(request, *callback_args, **callback_kwargs)
  File "/home/jing/python_server/tiaozy/application/ssl_users/views.py", line 198, in getMyPersonalInfo
    return handle_response(result)
NameError: global name 'handle_response' is not defined
[2015-04-24 10:29:28,791] [django.request] [ERROR] Internal Server Error: /get-my-personal-info
Traceback (most recent call last):
  File "/usr/local/lib/python2.7/dist-packages/django/core/handlers/base.py", line 111, in get_response
    response = wrapped_callback(request, *callback_args, **callback_kwargs)
  File "/home/jing/python_server/tiaozy/application/ssl_users/views.py", line 198, in getMyPersonalInfo
    return render(request,'/my_personal_info.html',{'result':result})
  File "/usr/local/lib/python2.7/dist-packages/django/shortcuts.py", line 50, in render
    return HttpResponse(loader.render_to_string(*args, **kwargs),
  File "/usr/local/lib/python2.7/dist-packages/django/template/loader.py", line 170, in render_to_string
    t = get_template(template_name, dirs)
  File "/usr/local/lib/python2.7/dist-packages/django/template/loader.py", line 144, in get_template
    template, origin = find_template(template_name, dirs)
  File "/usr/local/lib/python2.7/dist-packages/django/template/loader.py", line 136, in find_template
    raise TemplateDoesNotExist(name)
TemplateDoesNotExist: /my_personal_info.html
[2015-04-24 10:29:29,582] [django.request] [ERROR] Internal Server Error: /get-my-personal-info
Traceback (most recent call last):
  File "/usr/local/lib/python2.7/dist-packages/django/core/handlers/base.py", line 111, in get_response
    response = wrapped_callback(request, *callback_args, **callback_kwargs)
  File "/home/jing/python_server/tiaozy/application/ssl_users/views.py", line 198, in getMyPersonalInfo
    return render(request,'/my_personal_info.html',{'result':result})
  File "/usr/local/lib/python2.7/dist-packages/django/shortcuts.py", line 50, in render
    return HttpResponse(loader.render_to_string(*args, **kwargs),
  File "/usr/local/lib/python2.7/dist-packages/django/template/loader.py", line 170, in render_to_string
    t = get_template(template_name, dirs)
  File "/usr/local/lib/python2.7/dist-packages/django/template/loader.py", line 144, in get_template
    template, origin = find_template(template_name, dirs)
  File "/usr/local/lib/python2.7/dist-packages/django/template/loader.py", line 136, in find_template
    raise TemplateDoesNotExist(name)
TemplateDoesNotExist: /my_personal_info.html
[2015-04-23 20:41:57,175] [django.request] [ERROR] Internal Server Error: /open-my-center/
Traceback (most recent call last):
  File "/usr/local/lib/python2.7/dist-packages/Django-1.7.7-py2.7.egg/django/core/handlers/base.py", line 111, in get_response
    response = wrapped_callback(request, *callback_args, **callback_kwargs)
  File "/home/jing/python_app/tiaozy/application/ssl_users/views.py", line 177, in openMyCenter
    if not request.user.is_authenticated():
  File "/usr/local/lib/python2.7/dist-packages/Django-1.7.7-py2.7.egg/django/utils/functional.py", line 224, in inner
    self._setup()
  File "/usr/local/lib/python2.7/dist-packages/Django-1.7.7-py2.7.egg/django/utils/functional.py", line 357, in _setup
    self._wrapped = self._setupfunc()
  File "/usr/local/lib/python2.7/dist-packages/Django-1.7.7-py2.7.egg/django/contrib/auth/middleware.py", line 22, in <lambda>
    request.user = SimpleLazyObject(lambda: get_user(request))
  File "/usr/local/lib/python2.7/dist-packages/Django-1.7.7-py2.7.egg/django/contrib/auth/middleware.py", line 10, in get_user
    request._cached_user = auth.get_user(request)
  File "/usr/local/lib/python2.7/dist-packages/Django-1.7.7-py2.7.egg/django/contrib/auth/__init__.py", line 159, in get_user
    user = backend.get_user(user_id)
  File "/usr/local/lib/python2.7/dist-packages/Django-1.7.7-py2.7.egg/django/contrib/auth/backends.py", line 69, in get_user
    return UserModel._default_manager.get(pk=user_id)
  File "/usr/local/lib/python2.7/dist-packages/Django-1.7.7-py2.7.egg/django/db/models/manager.py", line 92, in manager_method
    return getattr(self.get_queryset(), name)(*args, **kwargs)
  File "/usr/local/lib/python2.7/dist-packages/Django-1.7.7-py2.7.egg/django/db/models/query.py", line 351, in get
    num = len(clone)
  File "/usr/local/lib/python2.7/dist-packages/Django-1.7.7-py2.7.egg/django/db/models/query.py", line 122, in __len__
    self._fetch_all()
  File "/usr/local/lib/python2.7/dist-packages/Django-1.7.7-py2.7.egg/django/db/models/query.py", line 966, in _fetch_all
    self._result_cache = list(self.iterator())
  File "/usr/local/lib/python2.7/dist-packages/Django-1.7.7-py2.7.egg/django/db/models/query.py", line 265, in iterator
    for row in compiler.results_iter():
  File "/usr/local/lib/python2.7/dist-packages/Django-1.7.7-py2.7.egg/django/db/models/sql/compiler.py", line 700, in results_iter
    for rows in self.execute_sql(MULTI):
  File "/usr/local/lib/python2.7/dist-packages/Django-1.7.7-py2.7.egg/django/db/models/sql/compiler.py", line 786, in execute_sql
    cursor.execute(sql, params)
  File "/usr/local/lib/python2.7/dist-packages/Django-1.7.7-py2.7.egg/django/db/backends/utils.py", line 81, in execute
    return super(CursorDebugWrapper, self).execute(sql, params)
  File "/usr/local/lib/python2.7/dist-packages/Django-1.7.7-py2.7.egg/django/db/backends/utils.py", line 65, in execute
    return self.cursor.execute(sql, params)
  File "/usr/local/lib/python2.7/dist-packages/Django-1.7.7-py2.7.egg/django/db/utils.py", line 94, in __exit__
    six.reraise(dj_exc_type, dj_exc_value, traceback)
  File "/usr/local/lib/python2.7/dist-packages/Django-1.7.7-py2.7.egg/django/db/backends/utils.py", line 65, in execute
    return self.cursor.execute(sql, params)
  File "/usr/local/lib/python2.7/dist-packages/Django-1.7.7-py2.7.egg/django/db/backends/sqlite3/base.py", line 485, in execute
    return Database.Cursor.execute(self, query, params)
OperationalError: no such column: ssl_users_tzy_users.AvatarUrl
[2015-04-23 21:52:07,545] [django.request] [ERROR] Internal Server Error: /open-my-center/
Traceback (most recent call last):
  File "/usr/local/lib/python2.7/dist-packages/Django-1.7.7-py2.7.egg/django/core/handlers/base.py", line 98, in get_response
    resolver_match = resolver.resolve(request.path_info)
  File "/usr/local/lib/python2.7/dist-packages/Django-1.7.7-py2.7.egg/django/core/urlresolvers.py", line 345, in resolve
    sub_match = pattern.resolve(new_path)
  File "/usr/local/lib/python2.7/dist-packages/Django-1.7.7-py2.7.egg/django/core/urlresolvers.py", line 345, in resolve
    sub_match = pattern.resolve(new_path)
  File "/usr/local/lib/python2.7/dist-packages/Django-1.7.7-py2.7.egg/django/core/urlresolvers.py", line 224, in resolve
    return ResolverMatch(self.callback, args, kwargs, self.name)
  File "/usr/local/lib/python2.7/dist-packages/Django-1.7.7-py2.7.egg/django/core/urlresolvers.py", line 231, in callback
    self._callback = get_callable(self._callback_str)
  File "/usr/local/lib/python2.7/dist-packages/Django-1.7.7-py2.7.egg/django/utils/lru_cache.py", line 101, in wrapper
    result = user_function(*args, **kwds)
  File "/usr/local/lib/python2.7/dist-packages/Django-1.7.7-py2.7.egg/django/core/urlresolvers.py", line 97, in get_callable
    mod = import_module(mod_name)
  File "/usr/lib/python2.7/importlib/__init__.py", line 37, in import_module
    __import__(name)
  File "/home/jing/python_app/tiaozy/application/ssl_users/views.py", line 229
    if !validateEmail(email):
       ^
SyntaxError: invalid syntax
[2015-04-28 15:47:04,809] [django.request] [ERROR] Internal Server Error: /static/toastr/toastr.min.css
Traceback (most recent call last):
  File "/root/django/django/core/handlers/base.py", line 222, in get_response
    response = middleware_method(request, response)
  File "/root/django/django/contrib/sessions/middleware.py", line 49, in process_response
    request.session.save()
  File "/root/django/django/contrib/sessions/backends/db.py", line 64, in save
    obj.save(force_insert=must_create, using=using)
  File "/root/django/django/db/models/base.py", line 676, in save
    force_update=force_update, update_fields=update_fields)
  File "/root/django/django/db/models/base.py", line 704, in save_base
    updated = self._save_table(raw, cls, force_insert, force_update, using, update_fields)
  File "/root/django/django/db/models/base.py", line 788, in _save_table
    result = self._do_insert(cls._base_manager, using, fields, update_pk, raw)
  File "/root/django/django/db/models/base.py", line 827, in _do_insert
    using=using, raw=raw)
  File "/root/django/django/db/models/manager.py", line 127, in manager_method
    return getattr(self.get_queryset(), name)(*args, **kwargs)
  File "/root/django/django/db/models/query.py", line 1026, in _insert
    return query.get_compiler(using=using).execute_sql(return_id)
  File "/root/django/django/db/models/sql/compiler.py", line 977, in execute_sql
    cursor.execute(sql, params)
  File "/root/django/django/db/backends/utils.py", line 64, in execute
    return self.cursor.execute(sql, params)
  File "/root/django/django/db/utils.py", line 95, in __exit__
    six.reraise(dj_exc_type, dj_exc_value, traceback)
  File "/root/django/django/db/backends/utils.py", line 64, in execute
    return self.cursor.execute(sql, params)
  File "/root/django/django/db/backends/mysql/base.py", line 124, in execute
    return self.cursor.execute(query, args)
  File "/usr/lib/python2.7/dist-packages/MySQLdb/cursors.py", line 174, in execute
    self.errorhandler(self, exc, value)
  File "/usr/lib/python2.7/dist-packages/MySQLdb/connections.py", line 36, in defaulterrorhandler
    raise errorclass, errorvalue
OperationalError: (1213, 'Deadlock found when trying to get lock; try restarting transaction')
