[2015-04-22 08:12:11,546] [django.request] [ERROR] Internal Server Error: /get-user-all-posts
Traceback (most recent call last):
  File "/usr/local/lib/python2.7/dist-packages/django/core/handlers/base.py", line 204, in get_response
    response = middleware_method(request, response)
  File "/usr/local/lib/python2.7/dist-packages/django/middleware/clickjacking.py", line 31, in process_response
    if response.get('X-Frame-Options', None) is not None:
AttributeError: 'list' object has no attribute 'get'
[2015-04-22 08:13:05,609] [django.request] [ERROR] Internal Server Error: /get-user-all-posts
Traceback (most recent call last):
  File "/usr/local/lib/python2.7/dist-packages/django/core/handlers/base.py", line 204, in get_response
    response = middleware_method(request, response)
  File "/usr/local/lib/python2.7/dist-packages/django/middleware/clickjacking.py", line 31, in process_response
    if response.get('X-Frame-Options', None) is not None:
AttributeError: 'list' object has no attribute 'get'
[2015-04-22 08:14:11,529] [django.request] [ERROR] Internal Server Error: /get-user-all-posts
Traceback (most recent call last):
  File "/usr/local/lib/python2.7/dist-packages/django/core/handlers/base.py", line 204, in get_response
    response = middleware_method(request, response)
  File "/usr/local/lib/python2.7/dist-packages/django/middleware/clickjacking.py", line 31, in process_response
    if response.get('X-Frame-Options', None) is not None:
AttributeError: 'list' object has no attribute 'get'
[2015-04-22 08:15:47,245] [django.request] [ERROR] Internal Server Error: /get-user-all-posts
Traceback (most recent call last):
  File "/usr/local/lib/python2.7/dist-packages/django/core/handlers/base.py", line 204, in get_response
    response = middleware_method(request, response)
  File "/usr/local/lib/python2.7/dist-packages/django/middleware/clickjacking.py", line 31, in process_response
    if response.get('X-Frame-Options', None) is not None:
AttributeError: 'list' object has no attribute 'get'
[2015-04-22 08:16:23,178] [django.request] [ERROR] Internal Server Error: /get-user-all-posts
Traceback (most recent call last):
  File "/usr/local/lib/python2.7/dist-packages/django/core/handlers/base.py", line 204, in get_response
    response = middleware_method(request, response)
  File "/usr/local/lib/python2.7/dist-packages/django/middleware/clickjacking.py", line 31, in process_response
    if response.get('X-Frame-Options', None) is not None:
AttributeError: 'list' object has no attribute 'get'
[2015-04-22 08:19:27,341] [django.request] [ERROR] Internal Server Error: /get-user-all-posts
Traceback (most recent call last):
  File "/usr/local/lib/python2.7/dist-packages/django/core/handlers/base.py", line 204, in get_response
    response = middleware_method(request, response)
  File "/usr/local/lib/python2.7/dist-packages/django/middleware/clickjacking.py", line 31, in process_response
    if response.get('X-Frame-Options', None) is not None:
AttributeError: 'list' object has no attribute 'get'
[2015-04-22 08:21:35,635] [django.request] [ERROR] Internal Server Error: /get-user-all-posts
Traceback (most recent call last):
  File "/usr/local/lib/python2.7/dist-packages/django/core/handlers/base.py", line 204, in get_response
    response = middleware_method(request, response)
  File "/usr/local/lib/python2.7/dist-packages/django/middleware/clickjacking.py", line 31, in process_response
    if response.get('X-Frame-Options', None) is not None:
AttributeError: 'list' object has no attribute 'get'
[2015-04-22 08:22:55,811] [django.request] [ERROR] Internal Server Error: /get-user-all-posts
Traceback (most recent call last):
  File "/usr/local/lib/python2.7/dist-packages/django/core/handlers/base.py", line 111, in get_response
    response = wrapped_callback(request, *callback_args, **callback_kwargs)
  File "/home/jing/python_server/tiaozy/application/display_items/views.py", line 312, in getAllPostsForUser
    print postUser
  File "/home/jing/python_server/tiaozy/application/ssl_users/models.py", line 15, in __str__
    return "username:%s\tphone:%s\temail:%s\t"%(self.username,self.mobilephone,self.email)
AttributeError: 'tzy_users' object has no attribute 'mobilephone'
[2015-04-22 08:23:22,508] [django.request] [ERROR] Internal Server Error: /get-user-all-posts
Traceback (most recent call last):
  File "/usr/local/lib/python2.7/dist-packages/django/core/handlers/base.py", line 111, in get_response
    response = wrapped_callback(request, *callback_args, **callback_kwargs)
  File "/home/jing/python_server/tiaozy/application/display_items/views.py", line 312, in getAllPostsForUser
    print postUser
  File "/home/jing/python_server/tiaozy/application/ssl_users/models.py", line 15, in __str__
    return "username:%s\tphone:%s\temail:%s\t"%(self.username,self.mobilephone,self.email)
AttributeError: 'tzy_users' object has no attribute 'mobilephone'
[2015-04-22 08:23:48,671] [django.request] [ERROR] Internal Server Error: /get-user-all-posts
Traceback (most recent call last):
  File "/usr/local/lib/python2.7/dist-packages/django/core/handlers/base.py", line 111, in get_response
    response = wrapped_callback(request, *callback_args, **callback_kwargs)
  File "/home/jing/python_server/tiaozy/application/display_items/views.py", line 312, in getAllPostsForUser
    print postUser
  File "/home/jing/python_server/tiaozy/application/ssl_users/models.py", line 15, in __str__
    return "username:%s\tphone:%s\temail:%s\t"%(self.username,self.mobilephone,self.email)
AttributeError: 'tzy_users' object has no attribute 'mobilephone'
[2015-04-22 08:26:49,192] [django.request] [ERROR] Internal Server Error: /get-user-all-posts
Traceback (most recent call last):
  File "/usr/local/lib/python2.7/dist-packages/django/core/handlers/base.py", line 204, in get_response
    response = middleware_method(request, response)
  File "/usr/local/lib/python2.7/dist-packages/django/middleware/clickjacking.py", line 31, in process_response
    if response.get('X-Frame-Options', None) is not None:
AttributeError: 'list' object has no attribute 'get'
[2015-04-22 08:27:15,441] [django.request] [ERROR] Internal Server Error: /get-user-all-posts
Traceback (most recent call last):
  File "/usr/local/lib/python2.7/dist-packages/django/core/handlers/base.py", line 204, in get_response
    response = middleware_method(request, response)
  File "/usr/local/lib/python2.7/dist-packages/django/middleware/clickjacking.py", line 31, in process_response
    if response.get('X-Frame-Options', None) is not None:
AttributeError: 'list' object has no attribute 'get'
[2015-04-22 08:28:43,096] [django.request] [ERROR] Internal Server Error: /get-user-all-posts
Traceback (most recent call last):
  File "/usr/local/lib/python2.7/dist-packages/django/core/handlers/base.py", line 204, in get_response
    response = middleware_method(request, response)
  File "/usr/local/lib/python2.7/dist-packages/django/middleware/clickjacking.py", line 31, in process_response
    if response.get('X-Frame-Options', None) is not None:
AttributeError: 'list' object has no attribute 'get'
[2015-04-22 08:31:03,213] [django.request] [ERROR] Internal Server Error: /get-user-all-posts
Traceback (most recent call last):
  File "/usr/local/lib/python2.7/dist-packages/django/core/handlers/base.py", line 204, in get_response
    response = middleware_method(request, response)
  File "/usr/local/lib/python2.7/dist-packages/django/middleware/clickjacking.py", line 31, in process_response
    if response.get('X-Frame-Options', None) is not None:
AttributeError: 'list' object has no attribute 'get'
[2015-04-22 08:34:43,058] [django.request] [ERROR] Internal Server Error: /get-user-all-posts
Traceback (most recent call last):
  File "/usr/local/lib/python2.7/dist-packages/django/core/handlers/base.py", line 204, in get_response
    response = middleware_method(request, response)
  File "/usr/local/lib/python2.7/dist-packages/django/middleware/clickjacking.py", line 31, in process_response
    if response.get('X-Frame-Options', None) is not None:
AttributeError: 'list' object has no attribute 'get'
[2015-04-22 08:35:39,091] [django.request] [ERROR] Internal Server Error: /get-user-all-posts
Traceback (most recent call last):
  File "/usr/local/lib/python2.7/dist-packages/django/core/handlers/base.py", line 87, in get_response
    response = middleware_method(request)
  File "/usr/local/lib/python2.7/dist-packages/django/middleware/common.py", line 72, in process_request
    if (not urlresolvers.is_valid_path(request.path_info, urlconf) and
  File "/usr/local/lib/python2.7/dist-packages/django/core/urlresolvers.py", line 619, in is_valid_path
    resolve(path, urlconf)
  File "/usr/local/lib/python2.7/dist-packages/django/core/urlresolvers.py", line 494, in resolve
    return get_resolver(urlconf).resolve(path)
  File "/usr/local/lib/python2.7/dist-packages/django/core/urlresolvers.py", line 345, in resolve
    sub_match = pattern.resolve(new_path)
  File "/usr/local/lib/python2.7/dist-packages/django/core/urlresolvers.py", line 345, in resolve
    sub_match = pattern.resolve(new_path)
  File "/usr/local/lib/python2.7/dist-packages/django/core/urlresolvers.py", line 224, in resolve
    return ResolverMatch(self.callback, args, kwargs, self.name)
  File "/usr/local/lib/python2.7/dist-packages/django/core/urlresolvers.py", line 231, in callback
    self._callback = get_callable(self._callback_str)
  File "/usr/local/lib/python2.7/dist-packages/django/utils/lru_cache.py", line 101, in wrapper
    result = user_function(*args, **kwds)
  File "/usr/local/lib/python2.7/dist-packages/django/core/urlresolvers.py", line 118, in get_callable
    (lookup_view, mod_name))
ViewDoesNotExist: Could not import application.display_items.views.getAllPostsForUser. View does not exist in module application.display_items.views.
[2015-04-22 08:36:24,269] [django.request] [ERROR] Internal Server Error: /get-user-all-posts
Traceback (most recent call last):
  File "/usr/local/lib/python2.7/dist-packages/django/core/handlers/base.py", line 87, in get_response
    response = middleware_method(request)
  File "/usr/local/lib/python2.7/dist-packages/django/middleware/common.py", line 72, in process_request
    if (not urlresolvers.is_valid_path(request.path_info, urlconf) and
  File "/usr/local/lib/python2.7/dist-packages/django/core/urlresolvers.py", line 619, in is_valid_path
    resolve(path, urlconf)
  File "/usr/local/lib/python2.7/dist-packages/django/core/urlresolvers.py", line 494, in resolve
    return get_resolver(urlconf).resolve(path)
  File "/usr/local/lib/python2.7/dist-packages/django/core/urlresolvers.py", line 345, in resolve
    sub_match = pattern.resolve(new_path)
  File "/usr/local/lib/python2.7/dist-packages/django/core/urlresolvers.py", line 345, in resolve
    sub_match = pattern.resolve(new_path)
  File "/usr/local/lib/python2.7/dist-packages/django/core/urlresolvers.py", line 224, in resolve
    return ResolverMatch(self.callback, args, kwargs, self.name)
  File "/usr/local/lib/python2.7/dist-packages/django/core/urlresolvers.py", line 231, in callback
    self._callback = get_callable(self._callback_str)
  File "/usr/local/lib/python2.7/dist-packages/django/utils/lru_cache.py", line 101, in wrapper
    result = user_function(*args, **kwds)
  File "/usr/local/lib/python2.7/dist-packages/django/core/urlresolvers.py", line 118, in get_callable
    (lookup_view, mod_name))
ViewDoesNotExist: Could not import application.display_items.views.getAllPostsForUser. View does not exist in module application.display_items.views.
[2015-04-22 08:38:01,596] [django.request] [ERROR] Internal Server Error: /get-user-all-posts
Traceback (most recent call last):
  File "/usr/local/lib/python2.7/dist-packages/django/core/handlers/base.py", line 87, in get_response
    response = middleware_method(request)
  File "/usr/local/lib/python2.7/dist-packages/django/middleware/common.py", line 72, in process_request
    if (not urlresolvers.is_valid_path(request.path_info, urlconf) and
  File "/usr/local/lib/python2.7/dist-packages/django/core/urlresolvers.py", line 619, in is_valid_path
    resolve(path, urlconf)
  File "/usr/local/lib/python2.7/dist-packages/django/core/urlresolvers.py", line 494, in resolve
    return get_resolver(urlconf).resolve(path)
  File "/usr/local/lib/python2.7/dist-packages/django/core/urlresolvers.py", line 345, in resolve
    sub_match = pattern.resolve(new_path)
  File "/usr/local/lib/python2.7/dist-packages/django/core/urlresolvers.py", line 345, in resolve
    sub_match = pattern.resolve(new_path)
  File "/usr/local/lib/python2.7/dist-packages/django/core/urlresolvers.py", line 224, in resolve
    return ResolverMatch(self.callback, args, kwargs, self.name)
  File "/usr/local/lib/python2.7/dist-packages/django/core/urlresolvers.py", line 231, in callback
    self._callback = get_callable(self._callback_str)
  File "/usr/local/lib/python2.7/dist-packages/django/utils/lru_cache.py", line 101, in wrapper
    result = user_function(*args, **kwds)
  File "/usr/local/lib/python2.7/dist-packages/django/core/urlresolvers.py", line 118, in get_callable
    (lookup_view, mod_name))
ViewDoesNotExist: Could not import application.display_items.views.getAllPostsForUser. View does not exist in module application.display_items.views.
[2015-04-22 14:41:01,121] [django.request] [ERROR] Internal Server Error: /get-on-selling
Traceback (most recent call last):
  File "/usr/local/lib/python2.7/dist-packages/Django-1.7.7-py2.7.egg/django/core/handlers/base.py", line 87, in get_response
    response = middleware_method(request)
  File "/usr/local/lib/python2.7/dist-packages/Django-1.7.7-py2.7.egg/django/middleware/common.py", line 72, in process_request
    if (not urlresolvers.is_valid_path(request.path_info, urlconf) and
  File "/usr/local/lib/python2.7/dist-packages/Django-1.7.7-py2.7.egg/django/core/urlresolvers.py", line 619, in is_valid_path
    resolve(path, urlconf)
  File "/usr/local/lib/python2.7/dist-packages/Django-1.7.7-py2.7.egg/django/core/urlresolvers.py", line 494, in resolve
    return get_resolver(urlconf).resolve(path)
  File "/usr/local/lib/python2.7/dist-packages/Django-1.7.7-py2.7.egg/django/core/urlresolvers.py", line 345, in resolve
    sub_match = pattern.resolve(new_path)
  File "/usr/local/lib/python2.7/dist-packages/Django-1.7.7-py2.7.egg/django/core/urlresolvers.py", line 345, in resolve
    sub_match = pattern.resolve(new_path)
  File "/usr/local/lib/python2.7/dist-packages/Django-1.7.7-py2.7.egg/django/core/urlresolvers.py", line 224, in resolve
    return ResolverMatch(self.callback, args, kwargs, self.name)
  File "/usr/local/lib/python2.7/dist-packages/Django-1.7.7-py2.7.egg/django/core/urlresolvers.py", line 231, in callback
    self._callback = get_callable(self._callback_str)
  File "/usr/local/lib/python2.7/dist-packages/Django-1.7.7-py2.7.egg/django/utils/lru_cache.py", line 101, in wrapper
    result = user_function(*args, **kwds)
  File "/usr/local/lib/python2.7/dist-packages/Django-1.7.7-py2.7.egg/django/core/urlresolvers.py", line 97, in get_callable
    mod = import_module(mod_name)
  File "/usr/lib/python2.7/importlib/__init__.py", line 37, in import_module
    __import__(name)
  File "/home/jing/python_app/tiaozy/application/display_items/views.py", line 13
    from application.display_items.models import
                                               ^
SyntaxError: invalid syntax
[2015-04-22 14:41:01,148] [django.request] [ERROR] Internal Server Error: /get-on-asking
Traceback (most recent call last):
  File "/usr/local/lib/python2.7/dist-packages/Django-1.7.7-py2.7.egg/django/core/handlers/base.py", line 87, in get_response
    response = middleware_method(request)
  File "/usr/local/lib/python2.7/dist-packages/Django-1.7.7-py2.7.egg/django/middleware/common.py", line 72, in process_request
    if (not urlresolvers.is_valid_path(request.path_info, urlconf) and
  File "/usr/local/lib/python2.7/dist-packages/Django-1.7.7-py2.7.egg/django/core/urlresolvers.py", line 619, in is_valid_path
    resolve(path, urlconf)
  File "/usr/local/lib/python2.7/dist-packages/Django-1.7.7-py2.7.egg/django/core/urlresolvers.py", line 494, in resolve
    return get_resolver(urlconf).resolve(path)
  File "/usr/local/lib/python2.7/dist-packages/Django-1.7.7-py2.7.egg/django/core/urlresolvers.py", line 345, in resolve
    sub_match = pattern.resolve(new_path)
  File "/usr/local/lib/python2.7/dist-packages/Django-1.7.7-py2.7.egg/django/core/urlresolvers.py", line 345, in resolve
    sub_match = pattern.resolve(new_path)
  File "/usr/local/lib/python2.7/dist-packages/Django-1.7.7-py2.7.egg/django/core/urlresolvers.py", line 224, in resolve
    return ResolverMatch(self.callback, args, kwargs, self.name)
  File "/usr/local/lib/python2.7/dist-packages/Django-1.7.7-py2.7.egg/django/core/urlresolvers.py", line 231, in callback
    self._callback = get_callable(self._callback_str)
  File "/usr/local/lib/python2.7/dist-packages/Django-1.7.7-py2.7.egg/django/utils/lru_cache.py", line 101, in wrapper
    result = user_function(*args, **kwds)
  File "/usr/local/lib/python2.7/dist-packages/Django-1.7.7-py2.7.egg/django/core/urlresolvers.py", line 97, in get_callable
    mod = import_module(mod_name)
  File "/usr/lib/python2.7/importlib/__init__.py", line 37, in import_module
    __import__(name)
  File "/home/jing/python_app/tiaozy/application/display_items/views.py", line 13
    from application.display_items.models import
                                               ^
SyntaxError: invalid syntax
[2015-04-22 14:42:46,125] [django.request] [ERROR] Internal Server Error: /get-on-selling
Traceback (most recent call last):
  File "/usr/local/lib/python2.7/dist-packages/Django-1.7.7-py2.7.egg/django/core/handlers/base.py", line 87, in get_response
    response = middleware_method(request)
  File "/usr/local/lib/python2.7/dist-packages/Django-1.7.7-py2.7.egg/django/middleware/common.py", line 72, in process_request
    if (not urlresolvers.is_valid_path(request.path_info, urlconf) and
  File "/usr/local/lib/python2.7/dist-packages/Django-1.7.7-py2.7.egg/django/core/urlresolvers.py", line 619, in is_valid_path
    resolve(path, urlconf)
  File "/usr/local/lib/python2.7/dist-packages/Django-1.7.7-py2.7.egg/django/core/urlresolvers.py", line 494, in resolve
    return get_resolver(urlconf).resolve(path)
  File "/usr/local/lib/python2.7/dist-packages/Django-1.7.7-py2.7.egg/django/core/urlresolvers.py", line 345, in resolve
    sub_match = pattern.resolve(new_path)
  File "/usr/local/lib/python2.7/dist-packages/Django-1.7.7-py2.7.egg/django/core/urlresolvers.py", line 345, in resolve
    sub_match = pattern.resolve(new_path)
  File "/usr/local/lib/python2.7/dist-packages/Django-1.7.7-py2.7.egg/django/core/urlresolvers.py", line 224, in resolve
    return ResolverMatch(self.callback, args, kwargs, self.name)
  File "/usr/local/lib/python2.7/dist-packages/Django-1.7.7-py2.7.egg/django/core/urlresolvers.py", line 231, in callback
    self._callback = get_callable(self._callback_str)
  File "/usr/local/lib/python2.7/dist-packages/Django-1.7.7-py2.7.egg/django/utils/lru_cache.py", line 101, in wrapper
    result = user_function(*args, **kwds)
  File "/usr/local/lib/python2.7/dist-packages/Django-1.7.7-py2.7.egg/django/core/urlresolvers.py", line 97, in get_callable
    mod = import_module(mod_name)
  File "/usr/lib/python2.7/importlib/__init__.py", line 37, in import_module
    __import__(name)
  File "/home/jing/python_app/tiaozy/application/display_items/views.py", line 295
    result["MessageCount"] = len(item_messages_table.objects.filter(Item=))
                                                                         ^
SyntaxError: invalid syntax
[2015-04-22 14:42:46,151] [django.request] [ERROR] Internal Server Error: /get-on-asking
Traceback (most recent call last):
  File "/usr/local/lib/python2.7/dist-packages/Django-1.7.7-py2.7.egg/django/core/handlers/base.py", line 87, in get_response
    response = middleware_method(request)
  File "/usr/local/lib/python2.7/dist-packages/Django-1.7.7-py2.7.egg/django/middleware/common.py", line 72, in process_request
    if (not urlresolvers.is_valid_path(request.path_info, urlconf) and
  File "/usr/local/lib/python2.7/dist-packages/Django-1.7.7-py2.7.egg/django/core/urlresolvers.py", line 619, in is_valid_path
    resolve(path, urlconf)
  File "/usr/local/lib/python2.7/dist-packages/Django-1.7.7-py2.7.egg/django/core/urlresolvers.py", line 494, in resolve
    return get_resolver(urlconf).resolve(path)
  File "/usr/local/lib/python2.7/dist-packages/Django-1.7.7-py2.7.egg/django/core/urlresolvers.py", line 345, in resolve
    sub_match = pattern.resolve(new_path)
  File "/usr/local/lib/python2.7/dist-packages/Django-1.7.7-py2.7.egg/django/core/urlresolvers.py", line 345, in resolve
    sub_match = pattern.resolve(new_path)
  File "/usr/local/lib/python2.7/dist-packages/Django-1.7.7-py2.7.egg/django/core/urlresolvers.py", line 224, in resolve
    return ResolverMatch(self.callback, args, kwargs, self.name)
  File "/usr/local/lib/python2.7/dist-packages/Django-1.7.7-py2.7.egg/django/core/urlresolvers.py", line 231, in callback
    self._callback = get_callable(self._callback_str)
  File "/usr/local/lib/python2.7/dist-packages/Django-1.7.7-py2.7.egg/django/utils/lru_cache.py", line 101, in wrapper
    result = user_function(*args, **kwds)
  File "/usr/local/lib/python2.7/dist-packages/Django-1.7.7-py2.7.egg/django/core/urlresolvers.py", line 97, in get_callable
    mod = import_module(mod_name)
  File "/usr/lib/python2.7/importlib/__init__.py", line 37, in import_module
    __import__(name)
  File "/home/jing/python_app/tiaozy/application/display_items/views.py", line 295
    result["MessageCount"] = len(item_messages_table.objects.filter(Item=))
                                                                         ^
SyntaxError: invalid syntax
[2015-04-22 14:43:01,116] [django.request] [ERROR] Internal Server Error: /get-on-selling
Traceback (most recent call last):
  File "/usr/local/lib/python2.7/dist-packages/Django-1.7.7-py2.7.egg/django/core/handlers/base.py", line 87, in get_response
    response = middleware_method(request)
  File "/usr/local/lib/python2.7/dist-packages/Django-1.7.7-py2.7.egg/django/middleware/common.py", line 72, in process_request
    if (not urlresolvers.is_valid_path(request.path_info, urlconf) and
  File "/usr/local/lib/python2.7/dist-packages/Django-1.7.7-py2.7.egg/django/core/urlresolvers.py", line 619, in is_valid_path
    resolve(path, urlconf)
  File "/usr/local/lib/python2.7/dist-packages/Django-1.7.7-py2.7.egg/django/core/urlresolvers.py", line 494, in resolve
    return get_resolver(urlconf).resolve(path)
  File "/usr/local/lib/python2.7/dist-packages/Django-1.7.7-py2.7.egg/django/core/urlresolvers.py", line 345, in resolve
    sub_match = pattern.resolve(new_path)
  File "/usr/local/lib/python2.7/dist-packages/Django-1.7.7-py2.7.egg/django/core/urlresolvers.py", line 345, in resolve
    sub_match = pattern.resolve(new_path)
  File "/usr/local/lib/python2.7/dist-packages/Django-1.7.7-py2.7.egg/django/core/urlresolvers.py", line 224, in resolve
    return ResolverMatch(self.callback, args, kwargs, self.name)
  File "/usr/local/lib/python2.7/dist-packages/Django-1.7.7-py2.7.egg/django/core/urlresolvers.py", line 231, in callback
    self._callback = get_callable(self._callback_str)
  File "/usr/local/lib/python2.7/dist-packages/Django-1.7.7-py2.7.egg/django/utils/lru_cache.py", line 101, in wrapper
    result = user_function(*args, **kwds)
  File "/usr/local/lib/python2.7/dist-packages/Django-1.7.7-py2.7.egg/django/core/urlresolvers.py", line 97, in get_callable
    mod = import_module(mod_name)
  File "/usr/lib/python2.7/importlib/__init__.py", line 37, in import_module
    __import__(name)
  File "/home/jing/python_app/tiaozy/application/display_items/views.py", line 295
    result["MessageCount"] = len(item_messages_table.objects.filter(Item=))
                                                                         ^
SyntaxError: invalid syntax
[2015-04-22 14:43:01,151] [django.request] [ERROR] Internal Server Error: /get-on-asking
Traceback (most recent call last):
  File "/usr/local/lib/python2.7/dist-packages/Django-1.7.7-py2.7.egg/django/core/handlers/base.py", line 87, in get_response
    response = middleware_method(request)
  File "/usr/local/lib/python2.7/dist-packages/Django-1.7.7-py2.7.egg/django/middleware/common.py", line 72, in process_request
    if (not urlresolvers.is_valid_path(request.path_info, urlconf) and
  File "/usr/local/lib/python2.7/dist-packages/Django-1.7.7-py2.7.egg/django/core/urlresolvers.py", line 619, in is_valid_path
    resolve(path, urlconf)
  File "/usr/local/lib/python2.7/dist-packages/Django-1.7.7-py2.7.egg/django/core/urlresolvers.py", line 494, in resolve
    return get_resolver(urlconf).resolve(path)
  File "/usr/local/lib/python2.7/dist-packages/Django-1.7.7-py2.7.egg/django/core/urlresolvers.py", line 345, in resolve
    sub_match = pattern.resolve(new_path)
  File "/usr/local/lib/python2.7/dist-packages/Django-1.7.7-py2.7.egg/django/core/urlresolvers.py", line 345, in resolve
    sub_match = pattern.resolve(new_path)
  File "/usr/local/lib/python2.7/dist-packages/Django-1.7.7-py2.7.egg/django/core/urlresolvers.py", line 224, in resolve
    return ResolverMatch(self.callback, args, kwargs, self.name)
  File "/usr/local/lib/python2.7/dist-packages/Django-1.7.7-py2.7.egg/django/core/urlresolvers.py", line 231, in callback
    self._callback = get_callable(self._callback_str)
  File "/usr/local/lib/python2.7/dist-packages/Django-1.7.7-py2.7.egg/django/utils/lru_cache.py", line 101, in wrapper
    result = user_function(*args, **kwds)
  File "/usr/local/lib/python2.7/dist-packages/Django-1.7.7-py2.7.egg/django/core/urlresolvers.py", line 97, in get_callable
    mod = import_module(mod_name)
  File "/usr/lib/python2.7/importlib/__init__.py", line 37, in import_module
    __import__(name)
  File "/home/jing/python_app/tiaozy/application/display_items/views.py", line 295
    result["MessageCount"] = len(item_messages_table.objects.filter(Item=))
                                                                         ^
SyntaxError: invalid syntax
[2015-04-23 03:00:10,117] [django.request] [ERROR] Internal Server Error: /open_item
Traceback (most recent call last):
  File "/usr/local/lib/python2.7/dist-packages/django/core/handlers/base.py", line 87, in get_response
    response = middleware_method(request)
  File "/usr/local/lib/python2.7/dist-packages/django/middleware/common.py", line 72, in process_request
    if (not urlresolvers.is_valid_path(request.path_info, urlconf) and
  File "/usr/local/lib/python2.7/dist-packages/django/core/urlresolvers.py", line 619, in is_valid_path
    resolve(path, urlconf)
  File "/usr/local/lib/python2.7/dist-packages/django/core/urlresolvers.py", line 494, in resolve
    return get_resolver(urlconf).resolve(path)
  File "/usr/local/lib/python2.7/dist-packages/django/core/urlresolvers.py", line 345, in resolve
    sub_match = pattern.resolve(new_path)
  File "/usr/local/lib/python2.7/dist-packages/django/core/urlresolvers.py", line 345, in resolve
    sub_match = pattern.resolve(new_path)
  File "/usr/local/lib/python2.7/dist-packages/django/core/urlresolvers.py", line 224, in resolve
    return ResolverMatch(self.callback, args, kwargs, self.name)
  File "/usr/local/lib/python2.7/dist-packages/django/core/urlresolvers.py", line 231, in callback
    self._callback = get_callable(self._callback_str)
  File "/usr/local/lib/python2.7/dist-packages/django/utils/lru_cache.py", line 101, in wrapper
    result = user_function(*args, **kwds)
  File "/usr/local/lib/python2.7/dist-packages/django/core/urlresolvers.py", line 97, in get_callable
    mod = import_module(mod_name)
  File "/usr/lib/python2.7/importlib/__init__.py", line 37, in import_module
    __import__(name)
  File "/home/jing/python_server/tiaozy/application/display_items/views.py", line 384
    result["PostTime"] = formatTime(message.PostTime,"%Y-%m-%d %H:%M")
                       ^
SyntaxError: invalid syntax
[2015-04-23 03:15:14,935] [django.request] [ERROR] Internal Server Error: /open_item
Traceback (most recent call last):
  File "/usr/local/lib/python2.7/dist-packages/django/core/handlers/base.py", line 87, in get_response
    response = middleware_method(request)
  File "/usr/local/lib/python2.7/dist-packages/django/middleware/common.py", line 72, in process_request
    if (not urlresolvers.is_valid_path(request.path_info, urlconf) and
  File "/usr/local/lib/python2.7/dist-packages/django/core/urlresolvers.py", line 619, in is_valid_path
    resolve(path, urlconf)
  File "/usr/local/lib/python2.7/dist-packages/django/core/urlresolvers.py", line 494, in resolve
    return get_resolver(urlconf).resolve(path)
  File "/usr/local/lib/python2.7/dist-packages/django/core/urlresolvers.py", line 345, in resolve
    sub_match = pattern.resolve(new_path)
  File "/usr/local/lib/python2.7/dist-packages/django/core/urlresolvers.py", line 345, in resolve
    sub_match = pattern.resolve(new_path)
  File "/usr/local/lib/python2.7/dist-packages/django/core/urlresolvers.py", line 224, in resolve
    return ResolverMatch(self.callback, args, kwargs, self.name)
  File "/usr/local/lib/python2.7/dist-packages/django/core/urlresolvers.py", line 231, in callback
    self._callback = get_callable(self._callback_str)
  File "/usr/local/lib/python2.7/dist-packages/django/utils/lru_cache.py", line 101, in wrapper
    result = user_function(*args, **kwds)
  File "/usr/local/lib/python2.7/dist-packages/django/core/urlresolvers.py", line 97, in get_callable
    mod = import_module(mod_name)
  File "/usr/lib/python2.7/importlib/__init__.py", line 37, in import_module
    __import__(name)
  File "/home/jing/python_server/tiaozy/application/display_items/views.py", line 355
    message_str = request.user.username+" : "+message
    ^
IndentationError: unexpected indent
[2015-04-23 16:57:14,658] [django.request] [ERROR] Internal Server Error: /get-ssl-eecp-books
Traceback (most recent call last):
  File "/usr/local/lib/python2.7/dist-packages/Django-1.7.7-py2.7.egg/django/core/handlers/base.py", line 87, in get_response
    response = middleware_method(request)
  File "/usr/local/lib/python2.7/dist-packages/Django-1.7.7-py2.7.egg/django/middleware/common.py", line 72, in process_request
    if (not urlresolvers.is_valid_path(request.path_info, urlconf) and
  File "/usr/local/lib/python2.7/dist-packages/Django-1.7.7-py2.7.egg/django/core/urlresolvers.py", line 619, in is_valid_path
    resolve(path, urlconf)
  File "/usr/local/lib/python2.7/dist-packages/Django-1.7.7-py2.7.egg/django/core/urlresolvers.py", line 494, in resolve
    return get_resolver(urlconf).resolve(path)
  File "/usr/local/lib/python2.7/dist-packages/Django-1.7.7-py2.7.egg/django/core/urlresolvers.py", line 345, in resolve
    sub_match = pattern.resolve(new_path)
  File "/usr/local/lib/python2.7/dist-packages/Django-1.7.7-py2.7.egg/django/core/urlresolvers.py", line 345, in resolve
    sub_match = pattern.resolve(new_path)
  File "/usr/local/lib/python2.7/dist-packages/Django-1.7.7-py2.7.egg/django/core/urlresolvers.py", line 224, in resolve
    return ResolverMatch(self.callback, args, kwargs, self.name)
  File "/usr/local/lib/python2.7/dist-packages/Django-1.7.7-py2.7.egg/django/core/urlresolvers.py", line 231, in callback
    self._callback = get_callable(self._callback_str)
  File "/usr/local/lib/python2.7/dist-packages/Django-1.7.7-py2.7.egg/django/utils/lru_cache.py", line 101, in wrapper
    result = user_function(*args, **kwds)
  File "/usr/local/lib/python2.7/dist-packages/Django-1.7.7-py2.7.egg/django/core/urlresolvers.py", line 118, in get_callable
    (lookup_view, mod_name))
ViewDoesNotExist: Could not import application.display_items.views.getSSLEecpnBooks. View does not exist in module application.display_items.views.
